Workbook

Sheet Summary
A1: Invoices & Credit Notes – Summary
A2: All figures below are formulas and update when Inputs change.
A4: Period | B4: =TEXT(Inputs!A5,"mmm yyyy")&" to "&TEXT(Inputs!A17,"mmm yyyy")&" ("&COUNT(Inputs!$A$5:$A$17)&" months)."
A5: Totals | B5: =TEXT(SUM(Inputs!$B$5:$B$17),"#,##0")&" invoices and "&TEXT(SUM(Inputs!$C$5:$C$17),"#,##0")&" credit notes; on average "&TEXT(AVERAGE(Inputs!$B$5:$B$17),"#,##0")&" invoices and "&TEXT(AVERAGE(Inputs!$C$5:$C$17),"#,##0")&" credit notes per month."
A6: Highest CNS | B6: =TEXT(INDEX(Inputs!$A$5:$A$17,MATCH(MAX(Inputs!$C$5:$C$17),Inputs!$C$5:$C$17,0)),"mmm yyyy")&" with "&TEXT(MAX(Inputs!$C$5:$C$17),"#,##0")&" credit notes."
A7: Lowest CNS | B7: =TEXT(INDEX(Inputs!$A$5:$A$17,MATCH(MIN(Inputs!$C$5:$C$17),Inputs!$C$5:$C$17,0)),"mmm yyyy")&" with "&TEXT(MIN(Inputs!$C$5:$C$17),"#,##0")&" credit notes."
A8: Highest invoices | B8: =TEXT(INDEX(Inputs!$A$5:$A$17,MATCH(MAX(Inputs!$B$5:$B$17),Inputs!$B$5:$B$17,0)),"mmm yyyy")&" with "&TEXT(MAX(Inputs!$B$5:$B$17),"#,##0")&" invoices."
A9: Top order types | B9: ="In "&TEXT('Report 3'!B3,"mmm yyyy")&" – "&TEXT('Report 3'!B4,"mmm yyyy")&": "&'Report 3'!B8&" "&TEXT('Report 3'!C8,"0.0%")&", "&'Report 3'!B9&" "&TEXT('Report 3'!C9,"0.0%")&", "&'Report 3'!B10&" "&TEXT('Report 3'!C10,"0.0%")&" (together "&TEXT('Report 3'!D10,"0.0%")&" of credit notes)."
A10: Invoice peaks | B10: ="Invoices exceed 1.5x the median month in "&COUNTIF(Inputs!$B$5:$B$17,">"&1.5*MEDIAN(Inputs!$B$5:$B$17))&" months, while CNS count does not rise with them."
A13: How to use
A14: • Edit only the yellow cells on the Inputs sheet (and the start / end month on Report 3).
A15: • Report 1: invoice and credit-note counts by month, with a chart and a written brief for every number.
A16: • Report 2: percentage of credit notes per order type, by month (heatmap table and 100% stacked chart).
A17: • Report 3: percentage of credit notes per order type over the chosen period (default Sep-2025 to Sep-2026).
A18: • Order type 'Unknown' is excluded. Percentages use the sum of the remaining order types as 100%.

Sheet Inputs
A1: Inputs – edit the yellow cells, every report and chart recalculates
A2: Months must stay in order from Sep-2025 onwards. Order type 'Unknown' is excluded from all reports.
A3: Invoice and credit note counts
A4: Month | B4: Invoices Count | C4: CNS Count
A5: 45901 | B5: 5416 | C5: 1028
A6: 45931 | B6: 10360 | C6: 2212
A7: 45962 | B7: 5496 | C7: 1338
A8: 45992 | B8: 5527 | C8: 598
A9: 46023 | B9: 10836 | C9: 703
A10: 46054 | B10: 5555 | C10: 1127
A11: 46082 | B11: 5586 | C11: 986
A12: 46113 | B12: 10638 | C12: 590
A13: 46143 | B13: 5623 | C13: 801
A14: 46174 | B14: 5668 | C14: 1038
A15: 46204 | B15: 9048 | C15: 658
A16: 46235 | B16: 5809 | C16: 1219
A17: 46266 | B17: 6254 | C17: 775
A20: Credit notes per order type (counts used for the percentages)
A21: Month | B21: Add New Hardware | C21: Add on Change | D21: Billing Reactivation | E21: Change WO Speed | F21: Downgrade | G21: Downgrade MSAN | H21: HW Replace | I21: Migration by E-Support | J21: Move Hardware | K21: New | L21: Price Change | M21: Sale Reactivation | N21: Sale Suspension | O21: Service Relocation | P21: Service Shift | Q21: Service Transfer | R21: Transmission Media Change | S21: Upgrade | T21: Upgrade MSAN | U21: Total
A22: =A5 | B22: 0 | C22: 0 | D22: 206 | E22: 10 | F22: 26 | G22: 2 | H22: 46 | I22: 0 | J22: 6 | K22: 3981 | L22: 358 | M22: 25 | N22: 22 | O22: 82 | P22: 2 | Q22: 247 | R22: 6 | S22: 170 | T22: 9 | U22: =SUM(B22:T22)
A23: =A6 | B23: 2 | C23: 0 | D23: 230 | E23: 0 | F23: 39 | G23: 3 | H23: 305 | I23: 0 | J23: 10 | K23: 8709 | L23: 781 | M23: 90 | N23: 648 | O23: 14 | P23: 4 | Q23: 10 | R23: 6 | S23: 881 | T23: 83 | U23: =SUM(B23:T23)
A24: =A7 | B24: 2 | C24: 0 | D24: 73 | E24: 9 | F24: 23 | G24: 3 | H24: 74 | I24: 2 | J24: 42 | K24: 2476 | L24: 163 | M24: 15 | N24: 138 | O24: 101 | P24: 20 | Q24: 122 | R24: 29 | S24: 343 | T24: 21 | U24: =SUM(B24:T24)
A25: =A8 | B25: 0 | C25: 1 | D25: 87 | E25: 8 | F25: 16 | G25: 0 | H25: 20 | I25: 0 | J25: 42 | K25: 1749 | L25: 491 | M25: 10 | N25: 48 | O25: 23 | P25: 2 | Q25: 506 | R25: 0 | S25: 125 | T25: 15 | U25: =SUM(B25:T25)
A26: =A9 | B26: 1 | C26: 0 | D26: 83 | E26: 4 | F26: 46 | G26: 1 | H26: 25 | I26: 1 | J26: 41 | K26: 5591 | L26: 1215 | M26: 6 | N26: 38 | O26: 14 | P26: 6 | Q26: 432 | R26: 14 | S26: 183 | T26: 22 | U26: =SUM(B26:T26)
A27: =A10 | B27: 0 | C27: 0 | D27: 72 | E27: 36 | F27: 96 | G27: 2 | H27: 265 | I27: 0 | J27: 35 | K27: 8608 | L27: 1756 | M27: 46 | N27: 74 | O27: 33 | P27: 6 | Q27: 335 | R27: 111 | S27: 331 | T27: 49 | U27: =SUM(B27:T27)
A28: =A11 | B28: 0 | C28: 0 | D28: 161 | E28: 9 | F28: 6 | G28: 3 | H28: 88 | I28: 0 | J28: 21 | K28: 1678 | L28: 612 | M28: 36 | N28: 65 | O28: 7 | P28: 9 | Q28: 485 | R28: 31 | S28: 174 | T28: 16 | U28: =SUM(B28:T28)
A29: =A12 | B29: 0 | C29: 0 | D29: 78 | E29: 8 | F29: 22 | G29: 0 | H29: 33 | I29: 0 | J29: 19 | K29: 1316 | L29: 156 | M29: 20 | N29: 34 | O29: 12 | P29: 4 | Q29: 1032 | R29: 11 | S29: 160 | T29: 29 | U29: =SUM(B29:T29)
A30: =A13 | B30: 10 | C30: 3 | D30: 32 | E30: 59 | F30: 54 | G30: 5 | H30: 25 | I30: 0 | J30: 36 | K30: 4275 | L30: 239 | M30: 25 | N30: 79 | O30: 20 | P30: 5 | Q30: 310 | R30: 11 | S30: 250 | T30: 58 | U30: =SUM(B30:T30)
A31: =A14 | B31: 0 | C31: 0 | D31: 75 | E31: 11 | F31: 30 | G31: 6 | H31: 23 | I31: 1 | J31: 35 | K31: 3765 | L31: 524 | M31: 15 | N31: 60 | O31: 11 | P31: 2 | Q31: 4299 | R31: 5 | S31: 257 | T31: 15 | U31: =SUM(B31:T31)
A32: =A15 | B32: 1 | C32: 0 | D32: 33 | E32: 14 | F32: 11 | G32: 2 | H32: 97 | I32: 0 | J32: 201 | K32: 4663 | L32: 1784 | M32: 13 | N32: 57 | O32: 134 | P32: 6 | Q32: 61 | R32: 7 | S32: 136 | T32: 52 | U32: =SUM(B32:T32)
A33: =A16 | B33: 0 | C33: 42 | D33: 67 | E33: 3 | F33: 37 | G33: 4 | H33: 94 | I33: 0 | J33: 121 | K33: 10412 | L33: 740 | M33: 23 | N33: 49 | O33: 142 | P33: 31 | Q33: 300 | R33: 38 | S33: 289 | T33: 31 | U33: =SUM(B33:T33)
A34: =A17 | B34: 9 | C34: 0 | D34: 128 | E34: 11 | F34: 28 | G34: 0 | H34: 189 | I34: 0 | J34: 37 | K34: 2622 | L34: 366 | M34: 13 | N34: 58 | O34: 20 | P34: 77 | Q34: 724 | R34: 26 | S34: 228 | T34: 18 | U34: =SUM(B34:T34)

Sheet Report 1
A1: Report 1 – Month · Invoices Count · CNS Count
A2: MoM = change versus the previous month.
A4: Month | B4: Invoices Count | C4: CNS Count | D4: Invoices MoM | E4: CNS MoM
A5: =Inputs!A5 | B5: =Inputs!B5 | C5: =Inputs!C5 | D5: – | E5: –
A6: =Inputs!A6 | B6: =Inputs!B6 | C6: =Inputs!C6 | D6: =IFERROR(B6/B5-1,0) | E6: =IFERROR(C6/C5-1,0)
A7: =Inputs!A7 | B7: =Inputs!B7 | C7: =Inputs!C7 | D7: =IFERROR(B7/B6-1,0) | E7: =IFERROR(C7/C6-1,0)
A8: =Inputs!A8 | B8: =Inputs!B8 | C8: =Inputs!C8 | D8: =IFERROR(B8/B7-1,0) | E8: =IFERROR(C8/C7-1,0)
A9: =Inputs!A9 | B9: =Inputs!B9 | C9: =Inputs!C9 | D9: =IFERROR(B9/B8-1,0) | E9: =IFERROR(C9/C8-1,0)
A10: =Inputs!A10 | B10: =Inputs!B10 | C10: =Inputs!C10 | D10: =IFERROR(B10/B9-1,0) | E10: =IFERROR(C10/C9-1,0)
A11: =Inputs!A11 | B11: =Inputs!B11 | C11: =Inputs!C11 | D11: =IFERROR(B11/B10-1,0) | E11: =IFERROR(C11/C10-1,0)
A12: =Inputs!A12 | B12: =Inputs!B12 | C12: =Inputs!C12 | D12: =IFERROR(B12/B11-1,0) | E12: =IFERROR(C12/C11-1,0)
A13: =Inputs!A13 | B13: =Inputs!B13 | C13: =Inputs!C13 | D13: =IFERROR(B13/B12-1,0) | E13: =IFERROR(C13/C12-1,0)
A14: =Inputs!A14 | B14: =Inputs!B14 | C14: =Inputs!C14 | D14: =IFERROR(B14/B13-1,0) | E14: =IFERROR(C14/C13-1,0)
A15: =Inputs!A15 | B15: =Inputs!B15 | C15: =Inputs!C15 | D15: =IFERROR(B15/B14-1,0) | E15: =IFERROR(C15/C14-1,0)
A16: =Inputs!A16 | B16: =Inputs!B16 | C16: =Inputs!C16 | D16: =IFERROR(B16/B15-1,0) | E16: =IFERROR(C16/C15-1,0)
A17: =Inputs!A17 | B17: =Inputs!B17 | C17: =Inputs!C17 | D17: =IFERROR(B17/B16-1,0) | E17: =IFERROR(C17/C16-1,0)
A18: Total | B18: =SUM(B5:B17) | C18: =SUM(C5:C17)
A19: Monthly avg | B19: =AVERAGE(B5:B17) | C19: =AVERAGE(C5:C17)
A22: Brief on each number
A23: =TEXT(A5,"mmm yyyy")&": "&TEXT(B5,"#,##0")&" invoices and "&TEXT(C5,"#,##0")&" credit notes. "&"This is the first month of the range, so there is no previous month to compare with. "&"CNS count is "&IF(C5>$C$19*1.25,"well above",IF(C5<$C$19*0.75,"well below","close to"))&" the "&TEXT($C$19,"#,##0")&" monthly average."
A24: =TEXT(A6,"mmm yyyy")&": "&TEXT(B6,"#,##0")&" invoices and "&TEXT(C6,"#,##0")&" credit notes. "&"Versus "&TEXT(A5,"mmm yyyy")&", invoices "&IF(D6>=0,"rose ","fell ")&TEXT(ABS(D6),"0.0%")&" and credit notes "&IF(E6>=0,"rose ","fell ")&TEXT(ABS(E6),"0.0%")&". "&"CNS count is "&IF(C6>$C$19*1.25,"well above",IF(C6<$C$19*0.75,"well below","close to"))&" the "&TEXT($C$19,"#,##0")&" monthly average."
A25: =TEXT(A7,"mmm yyyy")&": "&TEXT(B7,"#,##0")&" invoices and "&TEXT(C7,"#,##0")&" credit notes. "&"Versus "&TEXT(A6,"mmm yyyy")&", invoices "&IF(D7>=0,"rose ","fell ")&TEXT(ABS(D7),"0.0%")&" and credit notes "&IF(E7>=0,"rose ","fell ")&TEXT(ABS(E7),"0.0%")&". "&"CNS count is "&IF(C7>$C$19*1.25,"well above",IF(C7<$C$19*0.75,"well below","close to"))&" the "&TEXT($C$19,"#,##0")&" monthly average."
A26: =TEXT(A8,"mmm yyyy")&": "&TEXT(B8,"#,##0")&" invoices and "&TEXT(C8,"#,##0")&" credit notes. "&"Versus "&TEXT(A7,"mmm yyyy")&", invoices "&IF(D8>=0,"rose ","fell ")&TEXT(ABS(D8),"0.0%")&" and credit notes "&IF(E8>=0,"rose ","fell ")&TEXT(ABS(E8),"0.0%")&". "&"CNS count is "&IF(C8>$C$19*1.25,"well above",IF(C8<$C$19*0.75,"well below","close to"))&" the "&TEXT($C$19,"#,##0")&" monthly average."
A27: =TEXT(A9,"mmm yyyy")&": "&TEXT(B9,"#,##0")&" invoices and "&TEXT(C9,"#,##0")&" credit notes. "&"Versus "&TEXT(A8,"mmm yyyy")&", invoices "&IF(D9>=0,"rose ","fell ")&TEXT(ABS(D9),"0.0%")&" and credit notes "&IF(E9>=0,"rose ","fell ")&TEXT(ABS(E9),"0.0%")&". "&"CNS count is "&IF(C9>$C$19*1.25,"well above",IF(C9<$C$19*0.75,"well below","close to"))&" the "&TEXT($C$19,"#,##0")&" monthly average."
A28: =TEXT(A10,"mmm yyyy")&": "&TEXT(B10,"#,##0")&" invoices and "&TEXT(C10,"#,##0")&" credit notes. "&"Versus "&TEXT(A9,"mmm yyyy")&", invoices "&IF(D10>=0,"rose ","fell ")&TEXT(ABS(D10),"0.0%")&" and credit notes "&IF(E10>=0,"rose ","fell ")&TEXT(ABS(E10),"0.0%")&". "&"CNS count is "&IF(C10>$C$19*1.25,"well above",IF(C10<$C$19*0.75,"well below","close to"))&" the "&TEXT($C$19,"#,##0")&" monthly average."
A29: =TEXT(A11,"mmm yyyy")&": "&TEXT(B11,"#,##0")&" invoices and "&TEXT(C11,"#,##0")&" credit notes. "&"Versus "&TEXT(A10,"mmm yyyy")&", invoices "&IF(D11>=0,"rose ","fell ")&TEXT(ABS(D11),"0.0%")&" and credit notes "&IF(E11>=0,"rose ","fell ")&TEXT(ABS(E11),"0.0%")&". "&"CNS count is "&IF(C11>$C$19*1.25,"well above",IF(C11<$C$19*0.75,"well below","close to"))&" the "&TEXT($C$19,"#,##0")&" monthly average."
A30: =TEXT(A12,"mmm yyyy")&": "&TEXT(B12,"#,##0")&" invoices and "&TEXT(C12,"#,##0")&" credit notes. "&"Versus "&TEXT(A11,"mmm yyyy")&", invoices "&IF(D12>=0,"rose ","fell ")&TEXT(ABS(D12),"0.0%")&" and credit notes "&IF(E12>=0,"rose ","fell ")&TEXT(ABS(E12),"0.0%")&". "&"CNS count is "&IF(C12>$C$19*1.25,"well above",IF(C12<$C$19*0.75,"well below","close to"))&" the "&TEXT($C$19,"#,##0")&" monthly average."
A31: =TEXT(A13,"mmm yyyy")&": "&TEXT(B13,"#,##0")&" invoices and "&TEXT(C13,"#,##0")&" credit notes. "&"Versus "&TEXT(A12,"mmm yyyy")&", invoices "&IF(D13>=0,"rose ","fell ")&TEXT(ABS(D13),"0.0%")&" and credit notes "&IF(E13>=0,"rose ","fell ")&TEXT(ABS(E13),"0.0%")&". "&"CNS count is "&IF(C13>$C$19*1.25,"well above",IF(C13<$C$19*0.75,"well below","close to"))&" the "&TEXT($C$19,"#,##0")&" monthly average."
A32: =TEXT(A14,"mmm yyyy")&": "&TEXT(B14,"#,##0")&" invoices and "&TEXT(C14,"#,##0")&" credit notes. "&"Versus "&TEXT(A13,"mmm yyyy")&", invoices "&IF(D14>=0,"rose ","fell ")&TEXT(ABS(D14),"0.0%")&" and credit notes "&IF(E14>=0,"rose ","fell ")&TEXT(ABS(E14),"0.0%")&". "&"CNS count is "&IF(C14>$C$19*1.25,"well above",IF(C14<$C$19*0.75,"well below","close to"))&" the "&TEXT($C$19,"#,##0")&" monthly average."
A33: =TEXT(A15,"mmm yyyy")&": "&TEXT(B15,"#,##0")&" invoices and "&TEXT(C15,"#,##0")&" credit notes. "&"Versus "&TEXT(A14,"mmm yyyy")&", invoices "&IF(D15>=0,"rose ","fell ")&TEXT(ABS(D15),"0.0%")&" and credit notes "&IF(E15>=0,"rose ","fell ")&TEXT(ABS(E15),"0.0%")&". "&"CNS count is "&IF(C15>$C$19*1.25,"well above",IF(C15<$C$19*0.75,"well below","close to"))&" the "&TEXT($C$19,"#,##0")&" monthly average."
A34: =TEXT(A16,"mmm yyyy")&": "&TEXT(B16,"#,##0")&" invoices and "&TEXT(C16,"#,##0")&" credit notes. "&"Versus "&TEXT(A15,"mmm yyyy")&", invoices "&IF(D16>=0,"rose ","fell ")&TEXT(ABS(D16),"0.0%")&" and credit notes "&IF(E16>=0,"rose ","fell ")&TEXT(ABS(E16),"0.0%")&". "&"CNS count is "&IF(C16>$C$19*1.25,"well above",IF(C16<$C$19*0.75,"well below","close to"))&" the "&TEXT($C$19,"#,##0")&" monthly average."
A35: =TEXT(A17,"mmm yyyy")&": "&TEXT(B17,"#,##0")&" invoices and "&TEXT(C17,"#,##0")&" credit notes. "&"Versus "&TEXT(A16,"mmm yyyy")&", invoices "&IF(D17>=0,"rose ","fell ")&TEXT(ABS(D17),"0.0%")&" and credit notes "&IF(E17>=0,"rose ","fell ")&TEXT(ABS(E17),"0.0%")&". "&"CNS count is "&IF(C17>$C$19*1.25,"well above",IF(C17<$C$19*0.75,"well below","close to"))&" the "&TEXT($C$19,"#,##0")&" monthly average."
A36: ="Total: "&TEXT(B18,"#,##0")&" invoices (avg "&TEXT(B19,"#,##0")&" per month) and "&TEXT(C18,"#,##0")&" credit notes (avg "&TEXT(C19,"#,##0")&" per month) from "&TEXT(A5,"mmm yyyy")&" to "&TEXT(A17,"mmm yyyy")&"."

Sheet Calc
A1: Helper calculations (do not edit – feeds Reports 2 and 3)
A4: Month key | B4: ='Report 2'!B4 | C4: ='Report 2'!C4 | D4: ='Report 2'!D4 | E4: ='Report 2'!E4 | F4: ='Report 2'!F4 | G4: ='Report 2'!G4 | H4: ='Report 2'!H4 | I4: ='Report 2'!I4 | ... T4: ='Report 2'!T4 | W4: Top 1 | X4: Share 1 | Y4: Top 2 | Z4: Share 2 | AA4: Top 3 | AB4: Share 3 | AC4: Other types >=1% | AD4: Types <1% | AE4: Top 3 total
A5: ='Report 2'!A5 | B5: ='Report 2'!B5+(21-COLUMN())/1000000000 | C5: ='Report 2'!C5+(21-COLUMN())/1000000000 | D5: ='Report 2'!D5+(21-COLUMN())/1000000000 | E5: ='Report 2'!E5+(21-COLUMN())/1000000000 | F5: ='Report 2'!F5+(21-COLUMN())/1000000000 | G5: ='Report 2'!G5+(21-COLUMN())/1000000000 | H5: ='Report 2'!H5+(21-COLUMN())/1000000000 | I5: ='Report 2'!I5+(21-COLUMN())/1000000000 | ... T5: ='Report 2'!T5+(21-COLUMN())/1000000000 | W5: =INDEX('Report 2'!$B$4:$T$4,MATCH(LARGE(Calc!$B$5:$T$5,1),Calc!$B$5:$T$5,0)) | X5: =LARGE('Report 2'!$B5:$T5,1) | Y5: =INDEX('Report 2'!$B$4:$T$4,MATCH(LARGE(Calc!$B$5:$T$5,2),Calc!$B$5:$T$5,0)) | Z5: =LARGE('Report 2'!$B5:$T5,2) | AA5: =INDEX('Report 2'!$B$4:$T$4,MATCH(LARGE(Calc!$B$5:$T$5,3),Calc!$B$5:$T$5,0)) | AB5: =LARGE('Report 2'!$B5:$T5,3) | AC5: =COUNTIF('Report 2'!$B5:$T5,">=0.01")-COUNTIF(X5,">=0.01")-COUNTIF(Z5,">=0.01")-COUNTIF(AB5,">=0.01") | AD5: =COUNTIFS('Report 2'!$B5:$T5,">0",'Report 2'!$B5:$T5,"<0.01") | AE5: =X5+Z5+AB5
A6: ='Report 2'!A6 | B6: ='Report 2'!B6+(21-COLUMN())/1000000000 | C6: ='Report 2'!C6+(21-COLUMN())/1000000000 | D6: ='Report 2'!D6+(21-COLUMN())/1000000000 | E6: ='Report 2'!E6+(21-COLUMN())/1000000000 | F6: ='Report 2'!F6+(21-COLUMN())/1000000000 | G6: ='Report 2'!G6+(21-COLUMN())/1000000000 | H6: ='Report 2'!H6+(21-COLUMN())/1000000000 | I6: ='Report 2'!I6+(21-COLUMN())/1000000000 | ... T6: ='Report 2'!T6+(21-COLUMN())/1000000000 | W6: =INDEX('Report 2'!$B$4:$T$4,MATCH(LARGE(Calc!$B$6:$T$6,1),Calc!$B$6:$T$6,0)) | X6: =LARGE('Report 2'!$B6:$T6,1) | Y6: =INDEX('Report 2'!$B$4:$T$4,MATCH(LARGE(Calc!$B$6:$T$6,2),Calc!$B$6:$T$6,0)) | Z6: =LARGE('Report 2'!$B6:$T6,2) | AA6: =INDEX('Report 2'!$B$4:$T$4,MATCH(LARGE(Calc!$B$6:$T$6,3),Calc!$B$6:$T$6,0)) | AB6: =LARGE('Report 2'!$B6:$T6,3) | AC6: =COUNTIF('Report 2'!$B6:$T6,">=0.01")-COUNTIF(X6,">=0.01")-COUNTIF(Z6,">=0.01")-COUNTIF(AB6,">=0.01") | AD6: =COUNTIFS('Report 2'!$B6:$T6,">0",'Report 2'!$B6:$T6,"<0.01") | AE6: =X6+Z6+AB6
A7: ='Report 2'!A7 | B7: ='Report 2'!B7+(21-COLUMN())/1000000000 | C7: ='Report 2'!C7+(21-COLUMN())/1000000000 | D7: ='Report 2'!D7+(21-COLUMN())/1000000000 | E7: ='Report 2'!E7+(21-COLUMN())/1000000000 | F7: ='Report 2'!F7+(21-COLUMN())/1000000000 | G7: ='Report 2'!G7+(21-COLUMN())/1000000000 | H7: ='Report 2'!H7+(21-COLUMN())/1000000000 | I7: ='Report 2'!I7+(21-COLUMN())/1000000000 | ... T7: ='Report 2'!T7+(21-COLUMN())/1000000000 | W7: =INDEX('Report 2'!$B$4:$T$4,MATCH(LARGE(Calc!$B$7:$T$7,1),Calc!$B$7:$T$7,0)) | X7: =LARGE('Report 2'!$B7:$T7,1) | Y7: =INDEX('Report 2'!$B$4:$T$4,MATCH(LARGE(Calc!$B$7:$T$7,2),Calc!$B$7:$T$7,0)) | Z7: =LARGE('Report 2'!$B7:$T7,2) | AA7: =INDEX('Report 2'!$B$4:$T$4,MATCH(LARGE(Calc!$B$7:$T$7,3),Calc!$B$7:$T$7,0)) | AB7: =LARGE('Report 2'!$B7:$T7,3) | AC7: =COUNTIF('Report 2'!$B7:$T7,">=0.01")-COUNTIF(X7,">=0.01")-COUNTIF(Z7,">=0.01")-COUNTIF(AB7,">=0.01") | AD7: =COUNTIFS('Report 2'!$B7:$T7,">0",'Report 2'!$B7:$T7,"<0.01") | AE7: =X7+Z7+AB7
A8: ='Report 2'!A8 | B8: ='Report 2'!B8+(21-COLUMN())/1000000000 | C8: ='Report 2'!C8+(21-COLUMN())/1000000000 | D8: ='Report 2'!D8+(21-COLUMN())/1000000000 | E8: ='Report 2'!E8+(21-COLUMN())/1000000000 | F8: ='Report 2'!F8+(21-COLUMN())/1000000000 | G8: ='Report 2'!G8+(21-COLUMN())/1000000000 | H8: ='Report 2'!H8+(21-COLUMN())/1000000000 | I8: ='Report 2'!I8+(21-COLUMN())/1000000000 | ... T8: ='Report 2'!T8+(21-COLUMN())/1000000000 | W8: =INDEX('Report 2'!$B$4:$T$4,MATCH(LARGE(Calc!$B$8:$T$8,1),Calc!$B$8:$T$8,0)) | X8: =LARGE('Report 2'!$B8:$T8,1) | Y8: =INDEX('Report 2'!$B$4:$T$4,MATCH(LARGE(Calc!$B$8:$T$8,2),Calc!$B$8:$T$8,0)) | Z8: =LARGE('Report 2'!$B8:$T8,2) | AA8: =INDEX('Report 2'!$B$4:$T$4,MATCH(LARGE(Calc!$B$8:$T$8,3),Calc!$B$8:$T$8,0)) | AB8: =LARGE('Report 2'!$B8:$T8,3) | AC8: =COUNTIF('Report 2'!$B8:$T8,">=0.01")-COUNTIF(X8,">=0.01")-COUNTIF(Z8,">=0.01")-COUNTIF(AB8,">=0.01") | AD8: =COUNTIFS('Report 2'!$B8:$T8,">0",'Report 2'!$B8:$T8,"<0.01") | AE8: =X8+Z8+AB8
A9: ='Report 2'!A9 | B9: ='Report 2'!B9+(21-COLUMN())/1000000000 | C9: ='Report 2'!C9+(21-COLUMN())/1000000000 | D9: ='Report 2'!D9+(21-COLUMN())/1000000000 | E9: ='Report 2'!E9+(21-COLUMN())/1000000000 | F9: ='Report 2'!F9+(21-COLUMN())/1000000000 | G9: ='Report 2'!G9+(21-COLUMN())/1000000000 | H9: ='Report 2'!H9+(21-COLUMN())/1000000000 | I9: ='Report 2'!I9+(21-COLUMN())/1000000000 | ... T9: ='Report 2'!T9+(21-COLUMN())/1000000000 | W9: =INDEX('Report 2'!$B$4:$T$4,MATCH(LARGE(Calc!$B$9:$T$9,1),Calc!$B$9:$T$9,0)) | X9: =LARGE('Report 2'!$B9:$T9,1) | Y9: =INDEX('Report 2'!$B$4:$T$4,MATCH(LARGE(Calc!$B$9:$T$9,2),Calc!$B$9:$T$9,0)) | Z9: =LARGE('Report 2'!$B9:$T9,2) | AA9: =INDEX('Report 2'!$B$4:$T$4,MATCH(LARGE(Calc!$B$9:$T$9,3),Calc!$B$9:$T$9,0)) | AB9: =LARGE('Report 2'!$B9:$T9,3) | AC9: =COUNTIF('Report 2'!$B9:$T9,">=0.01")-COUNTIF(X9,">=0.01")-COUNTIF(Z9,">=0.01")-COUNTIF(AB9,">=0.01") | AD9: =COUNTIFS('Report 2'!$B9:$T9,">0",'Report 2'!$B9:$T9,"<0.01") | AE9: =X9+Z9+AB9
A10: ='Report 2'!A10 | B10: ='Report 2'!B10+(21-COLUMN())/1000000000 | C10: ='Report 2'!C10+(21-COLUMN())/1000000000 | D10: ='Report 2'!D10+(21-COLUMN())/1000000000 | E10: ='Report 2'!E10+(21-COLUMN())/1000000000 | F10: ='Report 2'!F10+(21-COLUMN())/1000000000 | G10: ='Report 2'!G10+(21-COLUMN())/1000000000 | H10: ='Report 2'!H10+(21-COLUMN())/1000000000 | I10: ='Report 2'!I10+(21-COLUMN())/1000000000 | ... T10: ='Report 2'!T10+(21-COLUMN())/1000000000 | W10: =INDEX('Report 2'!$B$4:$T$4,MATCH(LARGE(Calc!$B$10:$T$10,1),Calc!$B$10:$T$10,0)) | X10: =LARGE('Report 2'!$B10:$T10,1) | Y10: =INDEX('Report 2'!$B$4:$T$4,MATCH(LARGE(Calc!$B$10:$T$10,2),Calc!$B$10:$T$10,0)) | Z10: =LARGE('Report 2'!$B10:$T10,2) | AA10: =INDEX('Report 2'!$B$4:$T$4,MATCH(LARGE(Calc!$B$10:$T$10,3),Calc!$B$10:$T$10,0)) | AB10: =LARGE('Report 2'!$B10:$T10,3) | AC10: =COUNTIF('Report 2'!$B10:$T10,">=0.01")-COUNTIF(X10,">=0.01")-COUNTIF(Z10,">=0.01")-COUNTIF(AB10,">=0.01") | AD10: =COUNTIFS('Report 2'!$B10:$T10,">0",'Report 2'!$B10:$T10,"<0.01") | AE10: =X10+Z10+AB10
A11: ='Report 2'!A11 | B11: ='Report 2'!B11+(21-COLUMN())/1000000000 | C11: ='Report 2'!C11+(21-COLUMN())/1000000000 | D11: ='Report 2'!D11+(21-COLUMN())/1000000000 | E11: ='Report 2'!E11+(21-COLUMN())/1000000000 | F11: ='Report 2'!F11+(21-COLUMN())/1000000000 | G11: ='Report 2'!G11+(21-COLUMN())/1000000000 | H11: ='Report 2'!H11+(21-COLUMN())/1000000000 | I11: ='Report 2'!I11+(21-COLUMN())/1000000000 | ... T11: ='Report 2'!T11+(21-COLUMN())/1000000000 | W11: =INDEX('Report 2'!$B$4:$T$4,MATCH(LARGE(Calc!$B$11:$T$11,1),Calc!$B$11:$T$11,0)) | X11: =LARGE('Report 2'!$B11:$T11,1) | Y11: =INDEX('Report 2'!$B$4:$T$4,MATCH(LARGE(Calc!$B$11:$T$11,2),Calc!$B$11:$T$11,0)) | Z11: =LARGE('Report 2'!$B11:$T11,2) | AA11: =INDEX('Report 2'!$B$4:$T$4,MATCH(LARGE(Calc!$B$11:$T$11,3),Calc!$B$11:$T$11,0)) | AB11: =LARGE('Report 2'!$B11:$T11,3) | AC11: =COUNTIF('Report 2'!$B11:$T11,">=0.01")-COUNTIF(X11,">=0.01")-COUNTIF(Z11,">=0.01")-COUNTIF(AB11,">=0.01") | AD11: =COUNTIFS('Report 2'!$B11:$T11,">0",'Report 2'!$B11:$T11,"<0.01") | AE11: =X11+Z11+AB11
A12: ='Report 2'!A12 | B12: ='Report 2'!B12+(21-COLUMN())/1000000000 | C12: ='Report 2'!C12+(21-COLUMN())/1000000000 | D12: ='Report 2'!D12+(21-COLUMN())/1000000000 | E12: ='Report 2'!E12+(21-COLUMN())/1000000000 | F12: ='Report 2'!F12+(21-COLUMN())/1000000000 | G12: ='Report 2'!G12+(21-COLUMN())/1000000000 | H12: ='Report 2'!H12+(21-COLUMN())/1000000000 | I12: ='Report 2'!I12+(21-COLUMN())/1000000000 | ... T12: ='Report 2'!T12+(21-COLUMN())/1000000000 | W12: =INDEX('Report 2'!$B$4:$T$4,MATCH(LARGE(Calc!$B$12:$T$12,1),Calc!$B$12:$T$12,0)) | X12: =LARGE('Report 2'!$B12:$T12,1) | Y12: =INDEX('Report 2'!$B$4:$T$4,MATCH(LARGE(Calc!$B$12:$T$12,2),Calc!$B$12:$T$12,0)) | Z12: =LARGE('Report 2'!$B12:$T12,2) | AA12: =INDEX('Report 2'!$B$4:$T$4,MATCH(LARGE(Calc!$B$12:$T$12,3),Calc!$B$12:$T$12,0)) | AB12: =LARGE('Report 2'!$B12:$T12,3) | AC12: =COUNTIF('Report 2'!$B12:$T12,">=0.01")-COUNTIF(X12,">=0.01")-COUNTIF(Z12,">=0.01")-COUNTIF(AB12,">=0.01") | AD12: =COUNTIFS('Report 2'!$B12:$T12,">0",'Report 2'!$B12:$T12,"<0.01") | AE12: =X12+Z12+AB12
A13: ='Report 2'!A13 | B13: ='Report 2'!B13+(21-COLUMN())/1000000000 | C13: ='Report 2'!C13+(21-COLUMN())/1000000000 | D13: ='Report 2'!D13+(21-COLUMN())/1000000000 | E13: ='Report 2'!E13+(21-COLUMN())/1000000000 | F13: ='Report 2'!F13+(21-COLUMN())/1000000000 | G13: ='Report 2'!G13+(21-COLUMN())/1000000000 | H13: ='Report 2'!H13+(21-COLUMN())/1000000000 | I13: ='Report 2'!I13+(21-COLUMN())/1000000000 | ... T13: ='Report 2'!T13+(21-COLUMN())/1000000000 | W13: =INDEX('Report 2'!$B$4:$T$4,MATCH(LARGE(Calc!$B$13:$T$13,1),Calc!$B$13:$T$13,0)) | X13: =LARGE('Report 2'!$B13:$T13,1) | Y13: =INDEX('Report 2'!$B$4:$T$4,MATCH(LARGE(Calc!$B$13:$T$13,2),Calc!$B$13:$T$13,0)) | Z13: =LARGE('Report 2'!$B13:$T13,2) | AA13: =INDEX('Report 2'!$B$4:$T$4,MATCH(LARGE(Calc!$B$13:$T$13,3),Calc!$B$13:$T$13,0)) | AB13: =LARGE('Report 2'!$B13:$T13,3) | AC13: =COUNTIF('Report 2'!$B13:$T13,">=0.01")-COUNTIF(X13,">=0.01")-COUNTIF(Z13,">=0.01")-COUNTIF(AB13,">=0.01") | AD13: =COUNTIFS('Report 2'!$B13:$T13,">0",'Report 2'!$B13:$T13,"<0.01") | AE13: =X13+Z13+AB13
A14: ='Report 2'!A14 | B14: ='Report 2'!B14+(21-COLUMN())/1000000000 | C14: ='Report 2'!C14+(21-COLUMN())/1000000000 | D14: ='Report 2'!D14+(21-COLUMN())/1000000000 | E14: ='Report 2'!E14+(21-COLUMN())/1000000000 | F14: ='Report 2'!F14+(21-COLUMN())/1000000000 | G14: ='Report 2'!G14+(21-COLUMN())/1000000000 | H14: ='Report 2'!H14+(21-COLUMN())/1000000000 | I14: ='Report 2'!I14+(21-COLUMN())/1000000000 | ... T14: ='Report 2'!T14+(21-COLUMN())/1000000000 | W14: =INDEX('Report 2'!$B$4:$T$4,MATCH(LARGE(Calc!$B$14:$T$14,1),Calc!$B$14:$T$14,0)) | X14: =LARGE('Report 2'!$B14:$T14,1) | Y14: =INDEX('Report 2'!$B$4:$T$4,MATCH(LARGE(Calc!$B$14:$T$14,2),Calc!$B$14:$T$14,0)) | Z14: =LARGE('Report 2'!$B14:$T14,2) | AA14: =INDEX('Report 2'!$B$4:$T$4,MATCH(LARGE(Calc!$B$14:$T$14,3),Calc!$B$14:$T$14,0)) | AB14: =LARGE('Report 2'!$B14:$T14,3) | AC14: =COUNTIF('Report 2'!$B14:$T14,">=0.01")-COUNTIF(X14,">=0.01")-COUNTIF(Z14,">=0.01")-COUNTIF(AB14,">=0.01") | AD14: =COUNTIFS('Report 2'!$B14:$T14,">0",'Report 2'!$B14:$T14,"<0.01") | AE14: =X14+Z14+AB14
A15: ='Report 2'!A15 | B15: ='Report 2'!B15+(21-COLUMN())/1000000000 | C15: ='Report 2'!C15+(21-COLUMN())/1000000000 | D15: ='Report 2'!D15+(21-COLUMN())/1000000000 | E15: ='Report 2'!E15+(21-COLUMN())/1000000000 | F15: ='Report 2'!F15+(21-COLUMN())/1000000000 | G15: ='Report 2'!G15+(21-COLUMN())/1000000000 | H15: ='Report 2'!H15+(21-COLUMN())/1000000000 | I15: ='Report 2'!I15+(21-COLUMN())/1000000000 | ... T15: ='Report 2'!T15+(21-COLUMN())/1000000000 | W15: =INDEX('Report 2'!$B$4:$T$4,MATCH(LARGE(Calc!$B$15:$T$15,1),Calc!$B$15:$T$15,0)) | X15: =LARGE('Report 2'!$B15:$T15,1) | Y15: =INDEX('Report 2'!$B$4:$T$4,MATCH(LARGE(Calc!$B$15:$T$15,2),Calc!$B$15:$T$15,0)) | Z15: =LARGE('Report 2'!$B15:$T15,2) | AA15: =INDEX('Report 2'!$B$4:$T$4,MATCH(LARGE(Calc!$B$15:$T$15,3),Calc!$B$15:$T$15,0)) | AB15: =LARGE('Report 2'!$B15:$T15,3) | AC15: =COUNTIF('Report 2'!$B15:$T15,">=0.01")-COUNTIF(X15,">=0.01")-COUNTIF(Z15,">=0.01")-COUNTIF(AB15,">=0.01") | AD15: =COUNTIFS('Report 2'!$B15:$T15,">0",'Report 2'!$B15:$T15,"<0.01") | AE15: =X15+Z15+AB15
A16: ='Report 2'!A16 | B16: ='Report 2'!B16+(21-COLUMN())/1000000000 | C16: ='Report 2'!C16+(21-COLUMN())/1000000000 | D16: ='Report 2'!D16+(21-COLUMN())/1000000000 | E16: ='Report 2'!E16+(21-COLUMN())/1000000000 | F16: ='Report 2'!F16+(21-COLUMN())/1000000000 | G16: ='Report 2'!G16+(21-COLUMN())/1000000000 | H16: ='Report 2'!H16+(21-COLUMN())/1000000000 | I16: ='Report 2'!I16+(21-COLUMN())/1000000000 | ... T16: ='Report 2'!T16+(21-COLUMN())/1000000000 | W16: =INDEX('Report 2'!$B$4:$T$4,MATCH(LARGE(Calc!$B$16:$T$16,1),Calc!$B$16:$T$16,0)) | X16: =LARGE('Report 2'!$B16:$T16,1) | Y16: =INDEX('Report 2'!$B$4:$T$4,MATCH(LARGE(Calc!$B$16:$T$16,2),Calc!$B$16:$T$16,0)) | Z16: =LARGE('Report 2'!$B16:$T16,2) | AA16: =INDEX('Report 2'!$B$4:$T$4,MATCH(LARGE(Calc!$B$16:$T$16,3),Calc!$B$16:$T$16,0)) | AB16: =LARGE('Report 2'!$B16:$T16,3) | AC16: =COUNTIF('Report 2'!$B16:$T16,">=0.01")-COUNTIF(X16,">=0.01")-COUNTIF(Z16,">=0.01")-COUNTIF(AB16,">=0.01") | AD16: =COUNTIFS('Report 2'!$B16:$T16,">0",'Report 2'!$B16:$T16,"<0.01") | AE16: =X16+Z16+AB16
A17: ='Report 2'!A17 | B17: ='Report 2'!B17+(21-COLUMN())/1000000000 | C17: ='Report 2'!C17+(21-COLUMN())/1000000000 | D17: ='Report 2'!D17+(21-COLUMN())/1000000000 | E17: ='Report 2'!E17+(21-COLUMN())/1000000000 | F17: ='Report 2'!F17+(21-COLUMN())/1000000000 | G17: ='Report 2'!G17+(21-COLUMN())/1000000000 | H17: ='Report 2'!H17+(21-COLUMN())/1000000000 | I17: ='Report 2'!I17+(21-COLUMN())/1000000000 | ... T17: ='Report 2'!T17+(21-COLUMN())/1000000000 | W17: =INDEX('Report 2'!$B$4:$T$4,MATCH(LARGE(Calc!$B$17:$T$17,1),Calc!$B$17:$T$17,0)) | X17: =LARGE('Report 2'!$B17:$T17,1) | Y17: =INDEX('Report 2'!$B$4:$T$4,MATCH(LARGE(Calc!$B$17:$T$17,2),Calc!$B$17:$T$17,0)) | Z17: =LARGE('Report 2'!$B17:$T17,2) | AA17: =INDEX('Report 2'!$B$4:$T$4,MATCH(LARGE(Calc!$B$17:$T$17,3),Calc!$B$17:$T$17,0)) | AB17: =LARGE('Report 2'!$B17:$T17,3) | AC17: =COUNTIF('Report 2'!$B17:$T17,">=0.01")-COUNTIF(X17,">=0.01")-COUNTIF(Z17,">=0.01")-COUNTIF(AB17,">=0.01") | AD17: =COUNTIFS('Report 2'!$B17:$T17,">0",'Report 2'!$B17:$T17,"<0.01") | AE17: =X17+Z17+AB17
A18: ='Report 2'!A18 | B18: ='Report 2'!B18+(21-COLUMN())/1000000000 | C18: ='Report 2'!C18+(21-COLUMN())/1000000000 | D18: ='Report 2'!D18+(21-COLUMN())/1000000000 | E18: ='Report 2'!E18+(21-COLUMN())/1000000000 | F18: ='Report 2'!F18+(21-COLUMN())/1000000000 | G18: ='Report 2'!G18+(21-COLUMN())/1000000000 | H18: ='Report 2'!H18+(21-COLUMN())/1000000000 | I18: ='Report 2'!I18+(21-COLUMN())/1000000000 | ... T18: ='Report 2'!T18+(21-COLUMN())/1000000000
A22: Order type | B22: Credit notes in range | C22: Share | D22: Rank key | E22: Months present | F22: Peak monthly share | G22: Peak month
A23: =Inputs!B21 | B23: =SUMIFS(Inputs!B$22:B$34,Inputs!$A$22:$A$34,">="&'Report 3'!$B$3,Inputs!$A$22:$A$34,"<="&'Report 3'!$B$4) | C23: =IFERROR(B23/SUM($B$23:$B$41),0) | D23: =C23+(42-ROW())/1000000000 | E23: =COUNTIF(INDEX($B$45:$T$57,0,1),">0") | F23: =MAX(0,MAX(INDEX($B$45:$T$57,0,1))) | G23: =INDEX($A$45:$A$57,MATCH(MAX(INDEX($B$45:$T$57,0,1)),INDEX($B$45:$T$57,0,1),0))
A24: =Inputs!C21 | B24: =SUMIFS(Inputs!C$22:C$34,Inputs!$A$22:$A$34,">="&'Report 3'!$B$3,Inputs!$A$22:$A$34,"<="&'Report 3'!$B$4) | C24: =IFERROR(B24/SUM($B$23:$B$41),0) | D24: =C24+(42-ROW())/1000000000 | E24: =COUNTIF(INDEX($B$45:$T$57,0,2),">0") | F24: =MAX(0,MAX(INDEX($B$45:$T$57,0,2))) | G24: =INDEX($A$45:$A$57,MATCH(MAX(INDEX($B$45:$T$57,0,2)),INDEX($B$45:$T$57,0,2),0))
A25: =Inputs!D21 | B25: =SUMIFS(Inputs!D$22:D$34,Inputs!$A$22:$A$34,">="&'Report 3'!$B$3,Inputs!$A$22:$A$34,"<="&'Report 3'!$B$4) | C25: =IFERROR(B25/SUM($B$23:$B$41),0) | D25: =C25+(42-ROW())/1000000000 | E25: =COUNTIF(INDEX($B$45:$T$57,0,3),">0") | F25: =MAX(0,MAX(INDEX($B$45:$T$57,0,3))) | G25: =INDEX($A$45:$A$57,MATCH(MAX(INDEX($B$45:$T$57,0,3)),INDEX($B$45:$T$57,0,3),0))
A26: =Inputs!E21 | B26: =SUMIFS(Inputs!E$22:E$34,Inputs!$A$22:$A$34,">="&'Report 3'!$B$3,Inputs!$A$22:$A$34,"<="&'Report 3'!$B$4) | C26: =IFERROR(B26/SUM($B$23:$B$41),0) | D26: =C26+(42-ROW())/1000000000 | E26: =COUNTIF(INDEX($B$45:$T$57,0,4),">0") | F26: =MAX(0,MAX(INDEX($B$45:$T$57,0,4))) | G26: =INDEX($A$45:$A$57,MATCH(MAX(INDEX($B$45:$T$57,0,4)),INDEX($B$45:$T$57,0,4),0))
A27: =Inputs!F21 | B27: =SUMIFS(Inputs!F$22:F$34,Inputs!$A$22:$A$34,">="&'Report 3'!$B$3,Inputs!$A$22:$A$34,"<="&'Report 3'!$B$4) | C27: =IFERROR(B27/SUM($B$23:$B$41),0) | D27: =C27+(42-ROW())/1000000000 | E27: =COUNTIF(INDEX($B$45:$T$57,0,5),">0") | F27: =MAX(0,MAX(INDEX($B$45:$T$57,0,5))) | G27: =INDEX($A$45:$A$57,MATCH(MAX(INDEX($B$45:$T$57,0,5)),INDEX($B$45:$T$57,0,5),0))
A28: =Inputs!G21 | B28: =SUMIFS(Inputs!G$22:G$34,Inputs!$A$22:$A$34,">="&'Report 3'!$B$3,Inputs!$A$22:$A$34,"<="&'Report 3'!$B$4) | C28: =IFERROR(B28/SUM($B$23:$B$41),0) | D28: =C28+(42-ROW())/1000000000 | E28: =COUNTIF(INDEX($B$45:$T$57,0,6),">0") | F28: =MAX(0,MAX(INDEX($B$45:$T$57,0,6))) | G28: =INDEX($A$45:$A$57,MATCH(MAX(INDEX($B$45:$T$57,0,6)),INDEX($B$45:$T$57,0,6),0))
A29: =Inputs!H21 | B29: =SUMIFS(Inputs!H$22:H$34,Inputs!$A$22:$A$34,">="&'Report 3'!$B$3,Inputs!$A$22:$A$34,"<="&'Report 3'!$B$4) | C29: =IFERROR(B29/SUM($B$23:$B$41),0) | D29: =C29+(42-ROW())/1000000000 | E29: =COUNTIF(INDEX($B$45:$T$57,0,7),">0") | F29: =MAX(0,MAX(INDEX($B$45:$T$57,0,7))) | G29: =INDEX($A$45:$A$57,MATCH(MAX(INDEX($B$45:$T$57,0,7)),INDEX($B$45:$T$57,0,7),0))
A30: =Inputs!I21 | B30: =SUMIFS(Inputs!I$22:I$34,Inputs!$A$22:$A$34,">="&'Report 3'!$B$3,Inputs!$A$22:$A$34,"<="&'Report 3'!$B$4) | C30: =IFERROR(B30/SUM($B$23:$B$41),0) | D30: =C30+(42-ROW())/1000000000 | E30: =COUNTIF(INDEX($B$45:$T$57,0,8),">0") | F30: =MAX(0,MAX(INDEX($B$45:$T$57,0,8))) | G30: =INDEX($A$45:$A$57,MATCH(MAX(INDEX($B$45:$T$57,0,8)),INDEX($B$45:$T$57,0,8),0))
A31: =Inputs!J21 | B31: =SUMIFS(Inputs!J$22:J$34,Inputs!$A$22:$A$34,">="&'Report 3'!$B$3,Inputs!$A$22:$A$34,"<="&'Report 3'!$B$4) | C31: =IFERROR(B31/SUM($B$23:$B$41),0) | D31: =C31+(42-ROW())/1000000000 | E31: =COUNTIF(INDEX($B$45:$T$57,0,9),">0") | F31: =MAX(0,MAX(INDEX($B$45:$T$57,0,9))) | G31: =INDEX($A$45:$A$57,MATCH(MAX(INDEX($B$45:$T$57,0,9)),INDEX($B$45:$T$57,0,9),0))
A32: =Inputs!K21 | B32: =SUMIFS(Inputs!K$22:K$34,Inputs!$A$22:$A$34,">="&'Report 3'!$B$3,Inputs!$A$22:$A$34,"<="&'Report 3'!$B$4) | C32: =IFERROR(B32/SUM($B$23:$B$41),0) | D32: =C32+(42-ROW())/1000000000 | E32: =COUNTIF(INDEX($B$45:$T$57,0,10),">0") | F32: =MAX(0,MAX(INDEX($B$45:$T$57,0,10))) | G32: =INDEX($A$45:$A$57,MATCH(MAX(INDEX($B$45:$T$57,0,10)),INDEX($B$45:$T$57,0,10),0))
A33: =Inputs!L21 | B33: =SUMIFS(Inputs!L$22:L$34,Inputs!$A$22:$A$34,">="&'Report 3'!$B$3,Inputs!$A$22:$A$34,"<="&'Report 3'!$B$4) | C33: =IFERROR(B33/SUM($B$23:$B$41),0) | D33: =C33+(42-ROW())/1000000000 | E33: =COUNTIF(INDEX($B$45:$T$57,0,11),">0") | F33: =MAX(0,MAX(INDEX($B$45:$T$57,0,11))) | G33: =INDEX($A$45:$A$57,MATCH(MAX(INDEX($B$45:$T$57,0,11)),INDEX($B$45:$T$57,0,11),0))
A34: =Inputs!M21 | B34: =SUMIFS(Inputs!M$22:M$34,Inputs!$A$22:$A$34,">="&'Report 3'!$B$3,Inputs!$A$22:$A$34,"<="&'Report 3'!$B$4) | C34: =IFERROR(B34/SUM($B$23:$B$41),0) | D34: =C34+(42-ROW())/1000000000 | E34: =COUNTIF(INDEX($B$45:$T$57,0,12),">0") | F34: =MAX(0,MAX(INDEX($B$45:$T$57,0,12))) | G34: =INDEX($A$45:$A$57,MATCH(MAX(INDEX($B$45:$T$57,0,12)),INDEX($B$45:$T$57,0,12),0))
A35: =Inputs!N21 | B35: =SUMIFS(Inputs!N$22:N$34,Inputs!$A$22:$A$34,">="&'Report 3'!$B$3,Inputs!$A$22:$A$34,"<="&'Report 3'!$B$4) | C35: =IFERROR(B35/SUM($B$23:$B$41),0) | D35: =C35+(42-ROW())/1000000000 | E35: =COUNTIF(INDEX($B$45:$T$57,0,13),">0") | F35: =MAX(0,MAX(INDEX($B$45:$T$57,0,13))) | G35: =INDEX($A$45:$A$57,MATCH(MAX(INDEX($B$45:$T$57,0,13)),INDEX($B$45:$T$57,0,13),0))
A36: =Inputs!O21 | B36: =SUMIFS(Inputs!O$22:O$34,Inputs!$A$22:$A$34,">="&'Report 3'!$B$3,Inputs!$A$22:$A$34,"<="&'Report 3'!$B$4) | C36: =IFERROR(B36/SUM($B$23:$B$41),0) | D36: =C36+(42-ROW())/1000000000 | E36: =COUNTIF(INDEX($B$45:$T$57,0,14),">0") | F36: =MAX(0,MAX(INDEX($B$45:$T$57,0,14))) | G36: =INDEX($A$45:$A$57,MATCH(MAX(INDEX($B$45:$T$57,0,14)),INDEX($B$45:$T$57,0,14),0))
A37: =Inputs!P21 | B37: =SUMIFS(Inputs!P$22:P$34,Inputs!$A$22:$A$34,">="&'Report 3'!$B$3,Inputs!$A$22:$A$34,"<="&'Report 3'!$B$4) | C37: =IFERROR(B37/SUM($B$23:$B$41),0) | D37: =C37+(42-ROW())/1000000000 | E37: =COUNTIF(INDEX($B$45:$T$57,0,15),">0") | F37: =MAX(0,MAX(INDEX($B$45:$T$57,0,15))) | G37: =INDEX($A$45:$A$57,MATCH(MAX(INDEX($B$45:$T$57,0,15)),INDEX($B$45:$T$57,0,15),0))
A38: =Inputs!Q21 | B38: =SUMIFS(Inputs!Q$22:Q$34,Inputs!$A$22:$A$34,">="&'Report 3'!$B$3,Inputs!$A$22:$A$34,"<="&'Report 3'!$B$4) | C38: =IFERROR(B38/SUM($B$23:$B$41),0) | D38: =C38+(42-ROW())/1000000000 | E38: =COUNTIF(INDEX($B$45:$T$57,0,16),">0") | F38: =MAX(0,MAX(INDEX($B$45:$T$57,0,16))) | G38: =INDEX($A$45:$A$57,MATCH(MAX(INDEX($B$45:$T$57,0,16)),INDEX($B$45:$T$57,0,16),0))
A39: =Inputs!R21 | B39: =SUMIFS(Inputs!R$22:R$34,Inputs!$A$22:$A$34,">="&'Report 3'!$B$3,Inputs!$A$22:$A$34,"<="&'Report 3'!$B$4) | C39: =IFERROR(B39/SUM($B$23:$B$41),0) | D39: =C39+(42-ROW())/1000000000 | E39: =COUNTIF(INDEX($B$45:$T$57,0,17),">0") | F39: =MAX(0,MAX(INDEX($B$45:$T$57,0,17))) | G39: =INDEX($A$45:$A$57,MATCH(MAX(INDEX($B$45:$T$57,0,17)),INDEX($B$45:$T$57,0,17),0))
A40: =Inputs!S21 | B40: =SUMIFS(Inputs!S$22:S$34,Inputs!$A$22:$A$34,">="&'Report 3'!$B$3,Inputs!$A$22:$A$34,"<="&'Report 3'!$B$4) | C40: =IFERROR(B40/SUM($B$23:$B$41),0) | D40: =C40+(42-ROW())/1000000000 | E40: =COUNTIF(INDEX($B$45:$T$57,0,18),">0") | F40: =MAX(0,MAX(INDEX($B$45:$T$57,0,18))) | G40: =INDEX($A$45:$A$57,MATCH(MAX(INDEX($B$45:$T$57,0,18)),INDEX($B$45:$T$57,0,18),0))
A41: =Inputs!T21 | B41: =SUMIFS(Inputs!T$22:T$34,Inputs!$A$22:$A$34,">="&'Report 3'!$B$3,Inputs!$A$22:$A$34,"<="&'Report 3'!$B$4) | C41: =IFERROR(B41/SUM($B$23:$B$41),0) | D41: =C41+(42-ROW())/1000000000 | E41: =COUNTIF(INDEX($B$45:$T$57,0,19),">0") | F41: =MAX(0,MAX(INDEX($B$45:$T$57,0,19))) | G41: =INDEX($A$45:$A$57,MATCH(MAX(INDEX($B$45:$T$57,0,19)),INDEX($B$45:$T$57,0,19),0))
A44: Month (in range) | B44: ='Report 2'!B4 | C44: ='Report 2'!C4 | D44: ='Report 2'!D4 | E44: ='Report 2'!E4 | F44: ='Report 2'!F4 | G44: ='Report 2'!G4 | H44: ='Report 2'!H4 | I44: ='Report 2'!I4 | ... T44: ='Report 2'!T4
A45: =Inputs!A22 | B45: =IF(AND(Inputs!$A22>='Report 3'!$B$3,Inputs!$A22<='Report 3'!$B$4),'Report 2'!B5,-1) | C45: =IF(AND(Inputs!$A22>='Report 3'!$B$3,Inputs!$A22<='Report 3'!$B$4),'Report 2'!C5,-1) | D45: =IF(AND(Inputs!$A22>='Report 3'!$B$3,Inputs!$A22<='Report 3'!$B$4),'Report 2'!D5,-1) | E45: =IF(AND(Inputs!$A22>='Report 3'!$B$3,Inputs!$A22<='Report 3'!$B$4),'Report 2'!E5,-1) | F45: =IF(AND(Inputs!$A22>='Report 3'!$B$3,Inputs!$A22<='Report 3'!$B$4),'Report 2'!F5,-1) | G45: =IF(AND(Inputs!$A22>='Report 3'!$B$3,Inputs!$A22<='Report 3'!$B$4),'Report 2'!G5,-1) | H45: =IF(AND(Inputs!$A22>='Report 3'!$B$3,Inputs!$A22<='Report 3'!$B$4),'Report 2'!H5,-1) | I45: =IF(AND(Inputs!$A22>='Report 3'!$B$3,Inputs!$A22<='Report 3'!$B$4),'Report 2'!I5,-1) | ... T45: =IF(AND(Inputs!$A22>='Report 3'!$B$3,Inputs!$A22<='Report 3'!$B$4),'Report 2'!T5,-1)
A46: =Inputs!A23 | B46: =IF(AND(Inputs!$A23>='Report 3'!$B$3,Inputs!$A23<='Report 3'!$B$4),'Report 2'!B6,-1) | C46: =IF(AND(Inputs!$A23>='Report 3'!$B$3,Inputs!$A23<='Report 3'!$B$4),'Report 2'!C6,-1) | D46: =IF(AND(Inputs!$A23>='Report 3'!$B$3,Inputs!$A23<='Report 3'!$B$4),'Report 2'!D6,-1) | E46: =IF(AND(Inputs!$A23>='Report 3'!$B$3,Inputs!$A23<='Report 3'!$B$4),'Report 2'!E6,-1) | F46: =IF(AND(Inputs!$A23>='Report 3'!$B$3,Inputs!$A23<='Report 3'!$B$4),'Report 2'!F6,-1) | G46: =IF(AND(Inputs!$A23>='Report 3'!$B$3,Inputs!$A23<='Report 3'!$B$4),'Report 2'!G6,-1) | H46: =IF(AND(Inputs!$A23>='Report 3'!$B$3,Inputs!$A23<='Report 3'!$B$4),'Report 2'!H6,-1) | I46: =IF(AND(Inputs!$A23>='Report 3'!$B$3,Inputs!$A23<='Report 3'!$B$4),'Report 2'!I6,-1) | ... T46: =IF(AND(Inputs!$A23>='Report 3'!$B$3,Inputs!$A23<='Report 3'!$B$4),'Report 2'!T6,-1)
A47: =Inputs!A24 | B47: =IF(AND(Inputs!$A24>='Report 3'!$B$3,Inputs!$A24<='Report 3'!$B$4),'Report 2'!B7,-1) | C47: =IF(AND(Inputs!$A24>='Report 3'!$B$3,Inputs!$A24<='Report 3'!$B$4),'Report 2'!C7,-1) | D47: =IF(AND(Inputs!$A24>='Report 3'!$B$3,Inputs!$A24<='Report 3'!$B$4),'Report 2'!D7,-1) | E47: =IF(AND(Inputs!$A24>='Report 3'!$B$3,Inputs!$A24<='Report 3'!$B$4),'Report 2'!E7,-1) | F47: =IF(AND(Inputs!$A24>='Report 3'!$B$3,Inputs!$A24<='Report 3'!$B$4),'Report 2'!F7,-1) | G47: =IF(AND(Inputs!$A24>='Report 3'!$B$3,Inputs!$A24<='Report 3'!$B$4),'Report 2'!G7,-1) | H47: =IF(AND(Inputs!$A24>='Report 3'!$B$3,Inputs!$A24<='Report 3'!$B$4),'Report 2'!H7,-1) | I47: =IF(AND(Inputs!$A24>='Report 3'!$B$3,Inputs!$A24<='Report 3'!$B$4),'Report 2'!I7,-1) | ... T47: =IF(AND(Inputs!$A24>='Report 3'!$B$3,Inputs!$A24<='Report 3'!$B$4),'Report 2'!T7,-1)
...

Sheet Report 2
A1: Report 2 – Percentage of credit notes per order type, by month
A2: Each month adds up to 100%. Darker colour = bigger share. 'Unknown' excluded.
W3: Chart data (auto: top 7 order types by average share)
A4: Month | B4: =Inputs!B21 | C4: =Inputs!C21 | D4: =Inputs!D21 | E4: =Inputs!E21 | F4: =Inputs!F21 | G4: =Inputs!G21 | H4: =Inputs!H21 | I4: =Inputs!I21 | ... T4: =Inputs!T21 | W4: Month | X4: =INDEX('Report 2'!$B$4:$T$4,MATCH(LARGE(Calc!$B$18:$T$18,1),Calc!$B$18:$T$18,0)) | Y4: =INDEX('Report 2'!$B$4:$T$4,MATCH(LARGE(Calc!$B$18:$T$18,2),Calc!$B$18:$T$18,0)) | Z4: =INDEX('Report 2'!$B$4:$T$4,MATCH(LARGE(Calc!$B$18:$T$18,3),Calc!$B$18:$T$18,0)) | AA4: =INDEX('Report 2'!$B$4:$T$4,MATCH(LARGE(Calc!$B$18:$T$18,4),Calc!$B$18:$T$18,0)) | AB4: =INDEX('Report 2'!$B$4:$T$4,MATCH(LARGE(Calc!$B$18:$T$18,5),Calc!$B$18:$T$18,0)) | AC4: =INDEX('Report 2'!$B$4:$T$4,MATCH(LARGE(Calc!$B$18:$T$18,6),Calc!$B$18:$T$18,0)) | AD4: =INDEX('Report 2'!$B$4:$T$4,MATCH(LARGE(Calc!$B$18:$T$18,7),Calc!$B$18:$T$18,0)) | AE4: All other types
A5: =Inputs!A22 | B5: =IFERROR(Inputs!B22/Inputs!$U22,0) | C5: =IFERROR(Inputs!C22/Inputs!$U22,0) | D5: =IFERROR(Inputs!D22/Inputs!$U22,0) | E5: =IFERROR(Inputs!E22/Inputs!$U22,0) | F5: =IFERROR(Inputs!F22/Inputs!$U22,0) | G5: =IFERROR(Inputs!G22/Inputs!$U22,0) | H5: =IFERROR(Inputs!H22/Inputs!$U22,0) | I5: =IFERROR(Inputs!I22/Inputs!$U22,0) | ... T5: =IFERROR(Inputs!T22/Inputs!$U22,0) | W5: =A5 | X5: =INDEX($B5:$T5,MATCH(X$4,$B$4:$T$4,0)) | Y5: =INDEX($B5:$T5,MATCH(Y$4,$B$4:$T$4,0)) | Z5: =INDEX($B5:$T5,MATCH(Z$4,$B$4:$T$4,0)) | AA5: =INDEX($B5:$T5,MATCH(AA$4,$B$4:$T$4,0)) | AB5: =INDEX($B5:$T5,MATCH(AB$4,$B$4:$T$4,0)) | AC5: =INDEX($B5:$T5,MATCH(AC$4,$B$4:$T$4,0)) | AD5: =INDEX($B5:$T5,MATCH(AD$4,$B$4:$T$4,0)) | AE5: =MAX(0,1-SUM(X5:AD5))
A6: =Inputs!A23 | B6: =IFERROR(Inputs!B23/Inputs!$U23,0) | C6: =IFERROR(Inputs!C23/Inputs!$U23,0) | D6: =IFERROR(Inputs!D23/Inputs!$U23,0) | E6: =IFERROR(Inputs!E23/Inputs!$U23,0) | F6: =IFERROR(Inputs!F23/Inputs!$U23,0) | G6: =IFERROR(Inputs!G23/Inputs!$U23,0) | H6: =IFERROR(Inputs!H23/Inputs!$U23,0) | I6: =IFERROR(Inputs!I23/Inputs!$U23,0) | ... T6: =IFERROR(Inputs!T23/Inputs!$U23,0) | W6: =A6 | X6: =INDEX($B6:$T6,MATCH(X$4,$B$4:$T$4,0)) | Y6: =INDEX($B6:$T6,MATCH(Y$4,$B$4:$T$4,0)) | Z6: =INDEX($B6:$T6,MATCH(Z$4,$B$4:$T$4,0)) | AA6: =INDEX($B6:$T6,MATCH(AA$4,$B$4:$T$4,0)) | AB6: =INDEX($B6:$T6,MATCH(AB$4,$B$4:$T$4,0)) | AC6: =INDEX($B6:$T6,MATCH(AC$4,$B$4:$T$4,0)) | AD6: =INDEX($B6:$T6,MATCH(AD$4,$B$4:$T$4,0)) | AE6: =MAX(0,1-SUM(X6:AD6))
A7: =Inputs!A24 | B7: =IFERROR(Inputs!B24/Inputs!$U24,0) | C7: =IFERROR(Inputs!C24/Inputs!$U24,0) | D7: =IFERROR(Inputs!D24/Inputs!$U24,0) | E7: =IFERROR(Inputs!E24/Inputs!$U24,0) | F7: =IFERROR(Inputs!F24/Inputs!$U24,0) | G7: =IFERROR(Inputs!G24/Inputs!$U24,0) | H7: =IFERROR(Inputs!H24/Inputs!$U24,0) | I7: =IFERROR(Inputs!I24/Inputs!$U24,0) | ... T7: =IFERROR(Inputs!T24/Inputs!$U24,0) | W7: =A7 | X7: =INDEX($B7:$T7,MATCH(X$4,$B$4:$T$4,0)) | Y7: =INDEX($B7:$T7,MATCH(Y$4,$B$4:$T$4,0)) | Z7: =INDEX($B7:$T7,MATCH(Z$4,$B$4:$T$4,0)) | AA7: =INDEX($B7:$T7,MATCH(AA$4,$B$4:$T$4,0)) | AB7: =INDEX($B7:$T7,MATCH(AB$4,$B$4:$T$4,0)) | AC7: =INDEX($B7:$T7,MATCH(AC$4,$B$4:$T$4,0)) | AD7: =INDEX($B7:$T7,MATCH(AD$4,$B$4:$T$4,0)) | AE7: =MAX(0,1-SUM(X7:AD7))
A8: =Inputs!A25 | B8: =IFERROR(Inputs!B25/Inputs!$U25,0) | C8: =IFERROR(Inputs!C25/Inputs!$U25,0) | D8: =IFERROR(Inputs!D25/Inputs!$U25,0) | E8: =IFERROR(Inputs!E25/Inputs!$U25,0) | F8: =IFERROR(Inputs!F25/Inputs!$U25,0) | G8: =IFERROR(Inputs!G25/Inputs!$U25,0) | H8: =IFERROR(Inputs!H25/Inputs!$U25,0) | I8: =IFERROR(Inputs!I25/Inputs!$U25,0) | ... T8: =IFERROR(Inputs!T25/Inputs!$U25,0) | W8: =A8 | X8: =INDEX($B8:$T8,MATCH(X$4,$B$4:$T$4,0)) | Y8: =INDEX($B8:$T8,MATCH(Y$4,$B$4:$T$4,0)) | Z8: =INDEX($B8:$T8,MATCH(Z$4,$B$4:$T$4,0)) | AA8: =INDEX($B8:$T8,MATCH(AA$4,$B$4:$T$4,0)) | AB8: =INDEX($B8:$T8,MATCH(AB$4,$B$4:$T$4,0)) | AC8: =INDEX($B8:$T8,MATCH(AC$4,$B$4:$T$4,0)) | AD8: =INDEX($B8:$T8,MATCH(AD$4,$B$4:$T$4,0)) | AE8: =MAX(0,1-SUM(X8:AD8))
A9: =Inputs!A26 | B9: =IFERROR(Inputs!B26/Inputs!$U26,0) | C9: =IFERROR(Inputs!C26/Inputs!$U26,0) | D9: =IFERROR(Inputs!D26/Inputs!$U26,0) | E9: =IFERROR(Inputs!E26/Inputs!$U26,0) | F9: =IFERROR(Inputs!F26/Inputs!$U26,0) | G9: =IFERROR(Inputs!G26/Inputs!$U26,0) | H9: =IFERROR(Inputs!H26/Inputs!$U26,0) | I9: =IFERROR(Inputs!I26/Inputs!$U26,0) | ... T9: =IFERROR(Inputs!T26/Inputs!$U26,0) | W9: =A9 | X9: =INDEX($B9:$T9,MATCH(X$4,$B$4:$T$4,0)) | Y9: =INDEX($B9:$T9,MATCH(Y$4,$B$4:$T$4,0)) | Z9: =INDEX($B9:$T9,MATCH(Z$4,$B$4:$T$4,0)) | AA9: =INDEX($B9:$T9,MATCH(AA$4,$B$4:$T$4,0)) | AB9: =INDEX($B9:$T9,MATCH(AB$4,$B$4:$T$4,0)) | AC9: =INDEX($B9:$T9,MATCH(AC$4,$B$4:$T$4,0)) | AD9: =INDEX($B9:$T9,MATCH(AD$4,$B$4:$T$4,0)) | AE9: =MAX(0,1-SUM(X9:AD9))
A10: =Inputs!A27 | B10: =IFERROR(Inputs!B27/Inputs!$U27,0) | C10: =IFERROR(Inputs!C27/Inputs!$U27,0) | D10: =IFERROR(Inputs!D27/Inputs!$U27,0) | E10: =IFERROR(Inputs!E27/Inputs!$U27,0) | F10: =IFERROR(Inputs!F27/Inputs!$U27,0) | G10: =IFERROR(Inputs!G27/Inputs!$U27,0) | H10: =IFERROR(Inputs!H27/Inputs!$U27,0) | I10: =IFERROR(Inputs!I27/Inputs!$U27,0) | ... T10: =IFERROR(Inputs!T27/Inputs!$U27,0) | W10: =A10 | X10: =INDEX($B10:$T10,MATCH(X$4,$B$4:$T$4,0)) | Y10: =INDEX($B10:$T10,MATCH(Y$4,$B$4:$T$4,0)) | Z10: =INDEX($B10:$T10,MATCH(Z$4,$B$4:$T$4,0)) | AA10: =INDEX($B10:$T10,MATCH(AA$4,$B$4:$T$4,0)) | AB10: =INDEX($B10:$T10,MATCH(AB$4,$B$4:$T$4,0)) | AC10: =INDEX($B10:$T10,MATCH(AC$4,$B$4:$T$4,0)) | AD10: =INDEX($B10:$T10,MATCH(AD$4,$B$4:$T$4,0)) | AE10: =MAX(0,1-SUM(X10:AD10))
A11: =Inputs!A28 | B11: =IFERROR(Inputs!B28/Inputs!$U28,0) | C11: =IFERROR(Inputs!C28/Inputs!$U28,0) | D11: =IFERROR(Inputs!D28/Inputs!$U28,0) | E11: =IFERROR(Inputs!E28/Inputs!$U28,0) | F11: =IFERROR(Inputs!F28/Inputs!$U28,0) | G11: =IFERROR(Inputs!G28/Inputs!$U28,0) | H11: =IFERROR(Inputs!H28/Inputs!$U28,0) | I11: =IFERROR(Inputs!I28/Inputs!$U28,0) | ... T11: =IFERROR(Inputs!T28/Inputs!$U28,0) | W11: =A11 | X11: =INDEX($B11:$T11,MATCH(X$4,$B$4:$T$4,0)) | Y11: =INDEX($B11:$T11,MATCH(Y$4,$B$4:$T$4,0)) | Z11: =INDEX($B11:$T11,MATCH(Z$4,$B$4:$T$4,0)) | AA11: =INDEX($B11:$T11,MATCH(AA$4,$B$4:$T$4,0)) | AB11: =INDEX($B11:$T11,MATCH(AB$4,$B$4:$T$4,0)) | AC11: =INDEX($B11:$T11,MATCH(AC$4,$B$4:$T$4,0)) | AD11: =INDEX($B11:$T11,MATCH(AD$4,$B$4:$T$4,0)) | AE11: =MAX(0,1-SUM(X11:AD11))
A12: =Inputs!A29 | B12: =IFERROR(Inputs!B29/Inputs!$U29,0) | C12: =IFERROR(Inputs!C29/Inputs!$U29,0) | D12: =IFERROR(Inputs!D29/Inputs!$U29,0) | E12: =IFERROR(Inputs!E29/Inputs!$U29,0) | F12: =IFERROR(Inputs!F29/Inputs!$U29,0) | G12: =IFERROR(Inputs!G29/Inputs!$U29,0) | H12: =IFERROR(Inputs!H29/Inputs!$U29,0) | I12: =IFERROR(Inputs!I29/Inputs!$U29,0) | ... T12: =IFERROR(Inputs!T29/Inputs!$U29,0) | W12: =A12 | X12: =INDEX($B12:$T12,MATCH(X$4,$B$4:$T$4,0)) | Y12: =INDEX($B12:$T12,MATCH(Y$4,$B$4:$T$4,0)) | Z12: =INDEX($B12:$T12,MATCH(Z$4,$B$4:$T$4,0)) | AA12: =INDEX($B12:$T12,MATCH(AA$4,$B$4:$T$4,0)) | AB12: =INDEX($B12:$T12,MATCH(AB$4,$B$4:$T$4,0)) | AC12: =INDEX($B12:$T12,MATCH(AC$4,$B$4:$T$4,0)) | AD12: =INDEX($B12:$T12,MATCH(AD$4,$B$4:$T$4,0)) | AE12: =MAX(0,1-SUM(X12:AD12))
A13: =Inputs!A30 | B13: =IFERROR(Inputs!B30/Inputs!$U30,0) | C13: =IFERROR(Inputs!C30/Inputs!$U30,0) | D13: =IFERROR(Inputs!D30/Inputs!$U30,0) | E13: =IFERROR(Inputs!E30/Inputs!$U30,0) | F13: =IFERROR(Inputs!F30/Inputs!$U30,0) | G13: =IFERROR(Inputs!G30/Inputs!$U30,0) | H13: =IFERROR(Inputs!H30/Inputs!$U30,0) | I13: =IFERROR(Inputs!I30/Inputs!$U30,0) | ... T13: =IFERROR(Inputs!T30/Inputs!$U30,0) | W13: =A13 | X13: =INDEX($B13:$T13,MATCH(X$4,$B$4:$T$4,0)) | Y13: =INDEX($B13:$T13,MATCH(Y$4,$B$4:$T$4,0)) | Z13: =INDEX($B13:$T13,MATCH(Z$4,$B$4:$T$4,0)) | AA13: =INDEX($B13:$T13,MATCH(AA$4,$B$4:$T$4,0)) | AB13: =INDEX($B13:$T13,MATCH(AB$4,$B$4:$T$4,0)) | AC13: =INDEX($B13:$T13,MATCH(AC$4,$B$4:$T$4,0)) | AD13: =INDEX($B13:$T13,MATCH(AD$4,$B$4:$T$4,0)) | AE13: =MAX(0,1-SUM(X13:AD13))
A14: =Inputs!A31 | B14: =IFERROR(Inputs!B31/Inputs!$U31,0) | C14: =IFERROR(Inputs!C31/Inputs!$U31,0) | D14: =IFERROR(Inputs!D31/Inputs!$U31,0) | E14: =IFERROR(Inputs!E31/Inputs!$U31,0) | F14: =IFERROR(Inputs!F31/Inputs!$U31,0) | G14: =IFERROR(Inputs!G31/Inputs!$U31,0) | H14: =IFERROR(Inputs!H31/Inputs!$U31,0) | I14: =IFERROR(Inputs!I31/Inputs!$U31,0) | ... T14: =IFERROR(Inputs!T31/Inputs!$U31,0) | W14: =A14 | X14: =INDEX($B14:$T14,MATCH(X$4,$B$4:$T$4,0)) | Y14: =INDEX($B14:$T14,MATCH(Y$4,$B$4:$T$4,0)) | Z14: =INDEX($B14:$T14,MATCH(Z$4,$B$4:$T$4,0)) | AA14: =INDEX($B14:$T14,MATCH(AA$4,$B$4:$T$4,0)) | AB14: =INDEX($B14:$T14,MATCH(AB$4,$B$4:$T$4,0)) | AC14: =INDEX($B14:$T14,MATCH(AC$4,$B$4:$T$4,0)) | AD14: =INDEX($B14:$T14,MATCH(AD$4,$B$4:$T$4,0)) | AE14: =MAX(0,1-SUM(X14:AD14))
A15: =Inputs!A32 | B15: =IFERROR(Inputs!B32/Inputs!$U32,0) | C15: =IFERROR(Inputs!C32/Inputs!$U32,0) | D15: =IFERROR(Inputs!D32/Inputs!$U32,0) | E15: =IFERROR(Inputs!E32/Inputs!$U32,0) | F15: =IFERROR(Inputs!F32/Inputs!$U32,0) | G15: =IFERROR(Inputs!G32/Inputs!$U32,0) | H15: =IFERROR(Inputs!H32/Inputs!$U32,0) | I15: =IFERROR(Inputs!I32/Inputs!$U32,0) | ... T15: =IFERROR(Inputs!T32/Inputs!$U32,0) | W15: =A15 | X15: =INDEX($B15:$T15,MATCH(X$4,$B$4:$T$4,0)) | Y15: =INDEX($B15:$T15,MATCH(Y$4,$B$4:$T$4,0)) | Z15: =INDEX($B15:$T15,MATCH(Z$4,$B$4:$T$4,0)) | AA15: =INDEX($B15:$T15,MATCH(AA$4,$B$4:$T$4,0)) | AB15: =INDEX($B15:$T15,MATCH(AB$4,$B$4:$T$4,0)) | AC15: =INDEX($B15:$T15,MATCH(AC$4,$B$4:$T$4,0)) | AD15: =INDEX($B15:$T15,MATCH(AD$4,$B$4:$T$4,0)) | AE15: =MAX(0,1-SUM(X15:AD15))
A16: =Inputs!A33 | B16: =IFERROR(Inputs!B33/Inputs!$U33,0) | C16: =IFERROR(Inputs!C33/Inputs!$U33,0) | D16: =IFERROR(Inputs!D33/Inputs!$U33,0) | E16: =IFERROR(Inputs!E33/Inputs!$U33,0) | F16: =IFERROR(Inputs!F33/Inputs!$U33,0) | G16: =IFERROR(Inputs!G33/Inputs!$U33,0) | H16: =IFERROR(Inputs!H33/Inputs!$U33,0) | I16: =IFERROR(Inputs!I33/Inputs!$U33,0) | ... T16: =IFERROR(Inputs!T33/Inputs!$U33,0) | W16: =A16 | X16: =INDEX($B16:$T16,MATCH(X$4,$B$4:$T$4,0)) | Y16: =INDEX($B16:$T16,MATCH(Y$4,$B$4:$T$4,0)) | Z16: =INDEX($B16:$T16,MATCH(Z$4,$B$4:$T$4,0)) | AA16: =INDEX($B16:$T16,MATCH(AA$4,$B$4:$T$4,0)) | AB16: =INDEX($B16:$T16,MATCH(AB$4,$B$4:$T$4,0)) | AC16: =INDEX($B16:$T16,MATCH(AC$4,$B$4:$T$4,0)) | AD16: =INDEX($B16:$T16,MATCH(AD$4,$B$4:$T$4,0)) | AE16: =MAX(0,1-SUM(X16:AD16))
A17: =Inputs!A34 | B17: =IFERROR(Inputs!B34/Inputs!$U34,0) | C17: =IFERROR(Inputs!C34/Inputs!$U34,0) | D17: =IFERROR(Inputs!D34/Inputs!$U34,0) | E17: =IFERROR(Inputs!E34/Inputs!$U34,0) | F17: =IFERROR(Inputs!F34/Inputs!$U34,0) | G17: =IFERROR(Inputs!G34/Inputs!$U34,0) | H17: =IFERROR(Inputs!H34/Inputs!$U34,0) | I17: =IFERROR(Inputs!I34/Inputs!$U34,0) | ... T17: =IFERROR(Inputs!T34/Inputs!$U34,0) | W17: =A17 | X17: =INDEX($B17:$T17,MATCH(X$4,$B$4:$T$4,0)) | Y17: =INDEX($B17:$T17,MATCH(Y$4,$B$4:$T$4,0)) | Z17: =INDEX($B17:$T17,MATCH(Z$4,$B$4:$T$4,0)) | AA17: =INDEX($B17:$T17,MATCH(AA$4,$B$4:$T$4,0)) | AB17: =INDEX($B17:$T17,MATCH(AB$4,$B$4:$T$4,0)) | AC17: =INDEX($B17:$T17,MATCH(AC$4,$B$4:$T$4,0)) | AD17: =INDEX($B17:$T17,MATCH(AD$4,$B$4:$T$4,0)) | AE17: =MAX(0,1-SUM(X17:AD17))
A18: Average | B18: =AVERAGE(B5:B17) | C18: =AVERAGE(C5:C17) | D18: =AVERAGE(D5:D17) | E18: =AVERAGE(E5:E17) | F18: =AVERAGE(F5:F17) | G18: =AVERAGE(G5:G17) | H18: =AVERAGE(H5:H17) | I18: =AVERAGE(I5:I17) | ... T18: =AVERAGE(T5:T17)
A46: Brief on each month
A47: =TEXT(A5,"mmm yyyy")&": "&Calc!W5&" "&TEXT(Calc!X5,"0.0%")&", "&Calc!Y5&" "&TEXT(Calc!Z5,"0.0%")&", "&Calc!AA5&" "&TEXT(Calc!AB5,"0.0%")&". Top 3 = "&TEXT(Calc!AE5,"0.0%")&" of the month. The remaining "&TEXT(1-Calc!AE5,"0.0%")&" is spread over "&Calc!AC5&" other order types at 1% or more and "&Calc!AD5&" under 1%."
A48: =TEXT(A6,"mmm yyyy")&": "&Calc!W6&" "&TEXT(Calc!X6,"0.0%")&", "&Calc!Y6&" "&TEXT(Calc!Z6,"0.0%")&", "&Calc!AA6&" "&TEXT(Calc!AB6,"0.0%")&". Top 3 = "&TEXT(Calc!AE6,"0.0%")&" of the month. The remaining "&TEXT(1-Calc!AE6,"0.0%")&" is spread over "&Calc!AC6&" other order types at 1% or more and "&Calc!AD6&" under 1%."
A49: =TEXT(A7,"mmm yyyy")&": "&Calc!W7&" "&TEXT(Calc!X7,"0.0%")&", "&Calc!Y7&" "&TEXT(Calc!Z7,"0.0%")&", "&Calc!AA7&" "&TEXT(Calc!AB7,"0.0%")&". Top 3 = "&TEXT(Calc!AE7,"0.0%")&" of the month. The remaining "&TEXT(1-Calc!AE7,"0.0%")&" is spread over "&Calc!AC7&" other order types at 1% or more and "&Calc!AD7&" under 1%."
A50: =TEXT(A8,"mmm yyyy")&": "&Calc!W8&" "&TEXT(Calc!X8,"0.0%")&", "&Calc!Y8&" "&TEXT(Calc!Z8,"0.0%")&", "&Calc!AA8&" "&TEXT(Calc!AB8,"0.0%")&". Top 3 = "&TEXT(Calc!AE8,"0.0%")&" of the month. The remaining "&TEXT(1-Calc!AE8,"0.0%")&" is spread over "&Calc!AC8&" other order types at 1% or more and "&Calc!AD8&" under 1%."
A51: =TEXT(A9,"mmm yyyy")&": "&Calc!W9&" "&TEXT(Calc!X9,"0.0%")&", "&Calc!Y9&" "&TEXT(Calc!Z9,"0.0%")&", "&Calc!AA9&" "&TEXT(Calc!AB9,"0.0%")&". Top 3 = "&TEXT(Calc!AE9,"0.0%")&" of the month. The remaining "&TEXT(1-Calc!AE9,"0.0%")&" is spread over "&Calc!AC9&" other order types at 1% or more and "&Calc!AD9&" under 1%."
A52: =TEXT(A10,"mmm yyyy")&": "&Calc!W10&" "&TEXT(Calc!X10,"0.0%")&", "&Calc!Y10&" "&TEXT(Calc!Z10,"0.0%")&", "&Calc!AA10&" "&TEXT(Calc!AB10,"0.0%")&". Top 3 = "&TEXT(Calc!AE10,"0.0%")&" of the month. The remaining "&TEXT(1-Calc!AE10,"0.0%")&" is spread over "&Calc!AC10&" other order types at 1% or more and "&Calc!AD10&" under 1%."
A53: =TEXT(A11,"mmm yyyy")&": "&Calc!W11&" "&TEXT(Calc!X11,"0.0%")&", "&Calc!Y11&" "&TEXT(Calc!Z11,"0.0%")&", "&Calc!AA11&" "&TEXT(Calc!AB11,"0.0%")&". Top 3 = "&TEXT(Calc!AE11,"0.0%")&" of the month. The remaining "&TEXT(1-Calc!AE11,"0.0%")&" is spread over "&Calc!AC11&" other order types at 1% or more and "&Calc!AD11&" under 1%."
A54: =TEXT(A12,"mmm yyyy")&": "&Calc!W12&" "&TEXT(Calc!X12,"0.0%")&", "&Calc!Y12&" "&TEXT(Calc!Z12,"0.0%")&", "&Calc!AA12&" "&TEXT(Calc!AB12,"0.0%")&". Top 3 = "&TEXT(Calc!AE12,"0.0%")&" of the month. The remaining "&TEXT(1-Calc!AE12,"0.0%")&" is spread over "&Calc!AC12&" other order types at 1% or more and "&Calc!AD12&" under 1%."
A55: =TEXT(A13,"mmm yyyy")&": "&Calc!W13&" "&TEXT(Calc!X13,"0.0%")&", "&Calc!Y13&" "&TEXT(Calc!Z13,"0.0%")&", "&Calc!AA13&" "&TEXT(Calc!AB13,"0.0%")&". Top 3 = "&TEXT(Calc!AE13,"0.0%")&" of the month. The remaining "&TEXT(1-Calc!AE13,"0.0%")&" is spread over "&Calc!AC13&" other order types at 1% or more and "&Calc!AD13&" under 1%."
A56: =TEXT(A14,"mmm yyyy")&": "&Calc!W14&" "&TEXT(Calc!X14,"0.0%")&", "&Calc!Y14&" "&TEXT(Calc!Z14,"0.0%")&", "&Calc!AA14&" "&TEXT(Calc!AB14,"0.0%")&". Top 3 = "&TEXT(Calc!AE14,"0.0%")&" of the month. The remaining "&TEXT(1-Calc!AE14,"0.0%")&" is spread over "&Calc!AC14&" other order types at 1% or more and "&Calc!AD14&" under 1%."
A57: =TEXT(A15,"mmm yyyy")&": "&Calc!W15&" "&TEXT(Calc!X15,"0.0%")&", "&Calc!Y15&" "&TEXT(Calc!Z15,"0.0%")&", "&Calc!AA15&" "&TEXT(Calc!AB15,"0.0%")&". Top 3 = "&TEXT(Calc!AE15,"0.0%")&" of the month. The remaining "&TEXT(1-Calc!AE15,"0.0%")&" is spread over "&Calc!AC15&" other order types at 1% or more and "&Calc!AD15&" under 1%."
A58: =TEXT(A16,"mmm yyyy")&": "&Calc!W16&" "&TEXT(Calc!X16,"0.0%")&", "&Calc!Y16&" "&TEXT(Calc!Z16,"0.0%")&", "&Calc!AA16&" "&TEXT(Calc!AB16,"0.0%")&". Top 3 = "&TEXT(Calc!AE16,"0.0%")&" of the month. The remaining "&TEXT(1-Calc!AE16,"0.0%")&" is spread over "&Calc!AC16&" other order types at 1% or more and "&Calc!AD16&" under 1%."
A59: =TEXT(A17,"mmm yyyy")&": "&Calc!W17&" "&TEXT(Calc!X17,"0.0%")&", "&Calc!Y17&" "&TEXT(Calc!Z17,"0.0%")&", "&Calc!AA17&" "&TEXT(Calc!AB17,"0.0%")&". Top 3 = "&TEXT(Calc!AE17,"0.0%")&" of the month. The remaining "&TEXT(1-Calc!AE17,"0.0%")&" is spread over "&Calc!AC17&" other order types at 1% or more and "&Calc!AD17&" under 1%."
A62: Notable month-to-month shifts (top 5 order types by average share)
A63: =X$4&": from "&TEXT(MIN(INDEX($B$5:$T$17,0,MATCH(X$4,$B$4:$T$4,0))),"0.0%")&" ("&TEXT(INDEX($A$5:$A$17,MATCH(MIN(INDEX($B$5:$T$17,0,MATCH(X$4,$B$4:$T$4,0))),INDEX($B$5:$T$17,0,MATCH(X$4,$B$4:$T$4,0)),0)),"mmm yyyy")&") to "&TEXT(MAX(INDEX($B$5:$T$17,0,MATCH(X$4,$B$4:$T$4,0))),"0.0%")&" ("&TEXT(INDEX($A$5:$A$17,MATCH(MAX(INDEX($B$5:$T$17,0,MATCH(X$4,$B$4:$T$4,0))),INDEX($B$5:$T$17,0,MATCH(X$4,$B$4:$T$4,0)),0)),"mmm yyyy")&"), average monthly share "&TEXT(AVERAGE(INDEX($B$5:$T$17,0,MATCH(X$4,$B$4:$T$4,0))),"0.0%")&"."
A64: =Y$4&": from "&TEXT(MIN(INDEX($B$5:$T$17,0,MATCH(Y$4,$B$4:$T$4,0))),"0.0%")&" ("&TEXT(INDEX($A$5:$A$17,MATCH(MIN(INDEX($B$5:$T$17,0,MATCH(Y$4,$B$4:$T$4,0))),INDEX($B$5:$T$17,0,MATCH(Y$4,$B$4:$T$4,0)),0)),"mmm yyyy")&") to "&TEXT(MAX(INDEX($B$5:$T$17,0,MATCH(Y$4,$B$4:$T$4,0))),"0.0%")&" ("&TEXT(INDEX($A$5:$A$17,MATCH(MAX(INDEX($B$5:$T$17,0,MATCH(Y$4,$B$4:$T$4,0))),INDEX($B$5:$T$17,0,MATCH(Y$4,$B$4:$T$4,0)),0)),"mmm yyyy")&"), average monthly share "&TEXT(AVERAGE(INDEX($B$5:$T$17,0,MATCH(Y$4,$B$4:$T$4,0))),"0.0%")&"."
A65: =Z$4&": from "&TEXT(MIN(INDEX($B$5:$T$17,0,MATCH(Z$4,$B$4:$T$4,0))),"0.0%")&" ("&TEXT(INDEX($A$5:$A$17,MATCH(MIN(INDEX($B$5:$T$17,0,MATCH(Z$4,$B$4:$T$4,0))),INDEX($B$5:$T$17,0,MATCH(Z$4,$B$4:$T$4,0)),0)),"mmm yyyy")&") to "&TEXT(MAX(INDEX($B$5:$T$17,0,MATCH(Z$4,$B$4:$T$4,0))),"0.0%")&" ("&TEXT(INDEX($A$5:$A$17,MATCH(MAX(INDEX($B$5:$T$17,0,MATCH(Z$4,$B$4:$T$4,0))),INDEX($B$5:$T$17,0,MATCH(Z$4,$B$4:$T$4,0)),0)),"mmm yyyy")&"), average monthly share "&TEXT(AVERAGE(INDEX($B$5:$T$17,0,MATCH(Z$4,$B$4:$T$4,0))),"0.0%")&"."
A66: =AA$4&": from "&TEXT(MIN(INDEX($B$5:$T$17,0,MATCH(AA$4,$B$4:$T$4,0))),"0.0%")&" ("&TEXT(INDEX($A$5:$A$17,MATCH(MIN(INDEX($B$5:$T$17,0,MATCH(AA$4,$B$4:$T$4,0))),INDEX($B$5:$T$17,0,MATCH(AA$4,$B$4:$T$4,0)),0)),"mmm yyyy")&") to "&TEXT(MAX(INDEX($B$5:$T$17,0,MATCH(AA$4,$B$4:$T$4,0))),"0.0%")&" ("&TEXT(INDEX($A$5:$A$17,MATCH(MAX(INDEX($B$5:$T$17,0,MATCH(AA$4,$B$4:$T$4,0))),INDEX($B$5:$T$17,0,MATCH(AA$4,$B$4:$T$4,0)),0)),"mmm yyyy")&"), average monthly share "&TEXT(AVERAGE(INDEX($B$5:$T$17,0,MATCH(AA$4,$B$4:$T$4,0))),"0.0%")&"."
A67: =AB$4&": from "&TEXT(MIN(INDEX($B$5:$T$17,0,MATCH(AB$4,$B$4:$T$4,0))),"0.0%")&" ("&TEXT(INDEX($A$5:$A$17,MATCH(MIN(INDEX($B$5:$T$17,0,MATCH(AB$4,$B$4:$T$4,0))),INDEX($B$5:$T$17,0,MATCH(AB$4,$B$4:$T$4,0)),0)),"mmm yyyy")&") to "&TEXT(MAX(INDEX($B$5:$T$17,0,MATCH(AB$4,$B$4:$T$4,0))),"0.0%")&" ("&TEXT(INDEX($A$5:$A$17,MATCH(MAX(INDEX($B$5:$T$17,0,MATCH(AB$4,$B$4:$T$4,0))),INDEX($B$5:$T$17,0,MATCH(AB$4,$B$4:$T$4,0)),0)),"mmm yyyy")&"), average monthly share "&TEXT(AVERAGE(INDEX($B$5:$T$17,0,MATCH(AB$4,$B$4:$T$4,0))),"0.0%")&"."

Sheet Report 3
A1: Report 3 – Percentage of credit notes per order type over the period
A2: Change the yellow start / end months to re-cut the period. 'Unknown' excluded.
A3: Start month | B3: =Inputs!A5
A4: End month | B4: =Inputs!A17
A5: Months in range | B5: =COUNTIFS(Inputs!$A$22:$A$34,">="&$B$3,Inputs!$A$22:$A$34,"<="&$B$4)
A7: Rank | B7: Order type | C7: Share | D7: Running total
A8: 1 | B8: =INDEX(Calc!$A$23:$A$41,MATCH(LARGE(Calc!$D$23:$D$41,A8),Calc!$D$23:$D$41,0)) | C8: =INDEX(Calc!$C$23:$C$41,MATCH(LARGE(Calc!$D$23:$D$41,A8),Calc!$D$23:$D$41,0)) | D8: =SUM($C$8:C8)
A9: 2 | B9: =INDEX(Calc!$A$23:$A$41,MATCH(LARGE(Calc!$D$23:$D$41,A9),Calc!$D$23:$D$41,0)) | C9: =INDEX(Calc!$C$23:$C$41,MATCH(LARGE(Calc!$D$23:$D$41,A9),Calc!$D$23:$D$41,0)) | D9: =SUM($C$8:C9)
A10: 3 | B10: =INDEX(Calc!$A$23:$A$41,MATCH(LARGE(Calc!$D$23:$D$41,A10),Calc!$D$23:$D$41,0)) | C10: =INDEX(Calc!$C$23:$C$41,MATCH(LARGE(Calc!$D$23:$D$41,A10),Calc!$D$23:$D$41,0)) | D10: =SUM($C$8:C10)
A11: 4 | B11: =INDEX(Calc!$A$23:$A$41,MATCH(LARGE(Calc!$D$23:$D$41,A11),Calc!$D$23:$D$41,0)) | C11: =INDEX(Calc!$C$23:$C$41,MATCH(LARGE(Calc!$D$23:$D$41,A11),Calc!$D$23:$D$41,0)) | D11: =SUM($C$8:C11)
A12: 5 | B12: =INDEX(Calc!$A$23:$A$41,MATCH(LARGE(Calc!$D$23:$D$41,A12),Calc!$D$23:$D$41,0)) | C12: =INDEX(Calc!$C$23:$C$41,MATCH(LARGE(Calc!$D$23:$D$41,A12),Calc!$D$23:$D$41,0)) | D12: =SUM($C$8:C12)
A13: 6 | B13: =INDEX(Calc!$A$23:$A$41,MATCH(LARGE(Calc!$D$23:$D$41,A13),Calc!$D$23:$D$41,0)) | C13: =INDEX(Calc!$C$23:$C$41,MATCH(LARGE(Calc!$D$23:$D$41,A13),Calc!$D$23:$D$41,0)) | D13: =SUM($C$8:C13)
A14: 7 | B14: =INDEX(Calc!$A$23:$A$41,MATCH(LARGE(Calc!$D$23:$D$41,A14),Calc!$D$23:$D$41,0)) | C14: =INDEX(Calc!$C$23:$C$41,MATCH(LARGE(Calc!$D$23:$D$41,A14),Calc!$D$23:$D$41,0)) | D14: =SUM($C$8:C14)
A15: 8 | B15: =INDEX(Calc!$A$23:$A$41,MATCH(LARGE(Calc!$D$23:$D$41,A15),Calc!$D$23:$D$41,0)) | C15: =INDEX(Calc!$C$23:$C$41,MATCH(LARGE(Calc!$D$23:$D$41,A15),Calc!$D$23:$D$41,0)) | D15: =SUM($C$8:C15)
A16: 9 | B16: =INDEX(Calc!$A$23:$A$41,MATCH(LARGE(Calc!$D$23:$D$41,A16),Calc!$D$23:$D$41,0)) | C16: =INDEX(Calc!$C$23:$C$41,MATCH(LARGE(Calc!$D$23:$D$41,A16),Calc!$D$23:$D$41,0)) | D16: =SUM($C$8:C16)
A17: 10 | B17: =INDEX(Calc!$A$23:$A$41,MATCH(LARGE(Calc!$D$23:$D$41,A17),Calc!$D$23:$D$41,0)) | C17: =INDEX(Calc!$C$23:$C$41,MATCH(LARGE(Calc!$D$23:$D$41,A17),Calc!$D$23:$D$41,0)) | D17: =SUM($C$8:C17)
A18: 11 | B18: =INDEX(Calc!$A$23:$A$41,MATCH(LARGE(Calc!$D$23:$D$41,A18),Calc!$D$23:$D$41,0)) | C18: =INDEX(Calc!$C$23:$C$41,MATCH(LARGE(Calc!$D$23:$D$41,A18),Calc!$D$23:$D$41,0)) | D18: =SUM($C$8:C18)
A19: 12 | B19: =INDEX(Calc!$A$23:$A$41,MATCH(LARGE(Calc!$D$23:$D$41,A19),Calc!$D$23:$D$41,0)) | C19: =INDEX(Calc!$C$23:$C$41,MATCH(LARGE(Calc!$D$23:$D$41,A19),Calc!$D$23:$D$41,0)) | D19: =SUM($C$8:C19)
... A26: 19 | B26: =INDEX(Calc!$A$23:$A$41,MATCH(LARGE(Calc!$D$23:$D$41,A26),Calc!$D$23:$D$41,0)) | C26: =INDEX(Calc!$C$23:$C$41,MATCH(LARGE(Calc!$D$23:$D$41,A26),Calc!$D$23:$D$41,0)) | D26: =SUM($C$8:C26)
A28: Doughnut data (top 4 + all other types)
B29: Order type | C29: Share
B30: =B8 | C30: =C8
B31: =B9 | C31: =C9
B32: =B10 | C32: =C10
B33: =B11 | C33: =C11
B34: All other types | C34: =MAX(0,1-SUM(C30:C33))
A37: Brief on each order type
A38: ="Period: "&TEXT($B$3,"mmm yyyy")&" to "&TEXT($B$4,"mmm yyyy")&" ("&$B$5&" months). The top 3 order types make up "&TEXT(D10,"0.0%")&" of all credit notes."
A39: =B8&": "&IF(C8<0.0001,"<0.01%",TEXT(C8,IF(C8<0.01,"0.00%","0.0%")))&" of credit notes in the period (running total "&TEXT(D8,"0.0%")&"). Present in "&INDEX(Calc!$E$23:$E$41,MATCH(B8,Calc!$A$23:$A$41,0))&" of "&$B$5&" months; highest monthly share "&TEXT(INDEX(Calc!$F$23:$F$41,MATCH(B8,Calc!$A$23:$A$41,0)),"0.0%")&" in "&TEXT(INDEX(Calc!$G$23:$G$41,MATCH(B8,Calc!$A$23:$A$41,0)),"mmm yyyy")&"."
